Workbook

Sheet Form (2)
A1: OFFICE OF THE PROVINCIAL AGRICULTURIST
A2: CROP STATISTICS 2017
A6: Municipality: | C6: CUENCA
A7: Barangay: | C7: EMMANUEL
A9: No. | B9: NAME OF FARMER | C9: RICE | G9: CORN | K9: VEGETABLES | T9: FRUIT TREES | AE9: ROOT CROPS | AI9: SPICES | AN9: LEGUMES | AQ9: INDUSTRIAL CROPS | AV9: COCONUT | AW9: SUGARCANE | AX9: BAMBOO | AY9: GRAND TOTAL
C10: IRRIGATED | D10: RAINFED | E10: UPLAND | F10: TOTAL | G10: YELLOW | H10: WHITE | I10: GREEN | J10: TOTAL | K10: AMPALAYA | L10: EGGPLANT | M10: POLE SITAO | N10: OKRA | O10: SQUASH | P10: TOMATO | Q10: PECHAY | R10: MUSTARD | S10: TOTAL | T10: MANGO | U10: PAPAYA | V10: LANZONES | W10: RAMBUTAN | X10: TAMARIND | Y10: CITRUS | Z10: GUYABANO | AA10: ATIS | AB10: CHICO | AC10: DRAGON FRUIT | AD10: TOTAL | AE10: SWEET POTATO | AF10: UBE | AG10: GABI | AH10: TOTAL | AI10: BLACK PEPPER | AJ10: HOT PEPPER | AK10: GINGER | AL10: ONION | AM10: TOTAL | AN10: PEANUT | AO10: MUNGBEAN | AP10: TOTAL | AQ10: COFFEE | AR10: CACAO | AS10: PINEAPPLE | AT10: BANANA | AU10: TOTAL
C11: Area (ha) | D11: Area (ha) | E11: Area (ha) | F11: Area (ha) | G11: Area (ha) | H11: Area (ha) | I11: Area (ha) | J11: Area (ha) | K11: Area (ha) | L11: Area (ha) | M11: Area (ha) | N11: Area (ha) | O11: Area (ha) | P11: Area (ha) | Q11: Area (ha) | R11: Area (ha) | S11: Area (ha) | T11: Area (ha) | U11: Area (ha) | V11: Area (ha) | W11: Area (ha) | X11: Area (ha) | Y11: Area (ha) | Z11: Area (ha) | AA11: Area (ha) | AB11: Area (ha) | AC11: Area (ha) | AD11: Area (ha) | AE11: Area (ha) | AF11: Area (ha) | AG11: Area (ha) | AH11: Area (ha) | AI11: Area (ha) | AJ11: Area (ha) | AK11: Area (ha) | AL11: Area (ha) | AM11: Area (ha) | AN11: Area (ha) | AO11: Area (ha) | AP11: Area (ha) | AQ11: Area (ha) | AR11: Area (ha) | AS11: Area (ha) | AT11: Area (ha) | AU11: Area (ha) | AV11: Area (ha) | AW11: Area (ha) | AX11: Area (ha) | AY11: Area (ha)
A12: 1 | B12: Magsombol, Rommel | F12: =SUM(C12:E12) -> 0 | J12: =SUM(G12:I12) -> 0 | S12: =SUM(K12:R12) -> 0 | AD12: =SUM(T12:AC12) -> 0 | AH12: =SUM(AE12:AH12) -> 0 | AM12: =SUM(AI12:AM12) -> 0 | AP12: =SUM(AN12:AO12) -> 0 | AU12: =SUM(AQ12:AT12) -> 0 | AY12: =F12+J12+S12+AD12+AH12+AM12+AP12+AU12+AV12+AW12+AX12 -> 0
A13: 2 | B13: Yanga, Joselito | F13: =SUM(C13:E13) -> 0 | J13: =SUM(G13:I13) -> 0 | S13: =SUM(K13:R13) -> 0 | AD13: =SUM(T13:AC13) -> 0 | AH13: =SUM(AE13:AH13) -> 0 | AM13: =SUM(AI13:AM13) -> 0 | AP13: =SUM(AN13:AO13) -> 0 | AU13: =SUM(AQ13:AT13) -> 0 | AY13: =F13+J13+S13+AD13+AH13+AM13+AP13+AU13+AV13+AW13+AX13 -> 0
A14: 3 | B14: Landoy, Dioselda | F14: =SUM(C14:E14) -> 0 | J14: =SUM(G14:I14) -> 0 | S14: =SUM(K14:R14) -> 0 | AD14: =SUM(T14:AC14) -> 0 | AH14: =SUM(AE14:AH14) -> 0 | AM14: =SUM(AI14:AM14) -> 0 | AP14: =SUM(AN14:AO14) -> 0 | AU14: =SUM(AQ14:AT14) -> 0 | AY14: =F14+J14+S14+AD14+AH14+AM14+AP14+AU14+AV14+AW14+AX14 -> 0
A15: 4 | B15: Naz, Chona | F15: =SUM(C15:E15) -> 0 | J15: =SUM(G15:I15) -> 0 | S15: =SUM(K15:R15) -> 0 | AD15: =SUM(T15:AC15) -> 0 | AH15: =SUM(AE15:AH15) -> 0 | AM15: =SUM(AI15:AM15) -> 0 | AP15: =SUM(AN15:AO15) -> 0 | AU15: =SUM(AQ15:AT15) -> 0 | AY15: =F15+J15+S15+AD15+AH15+AM15+AP15+AU15+AV15+AW15+AX15 -> 0
A16: 5 | B16: Proseso, Robin | F16: =SUM(C16:E16) -> 0 | J16: =SUM(G16:I16) -> 0 | S16: =SUM(K16:R16) -> 0 | AD16: =SUM(T16:AC16) -> 0 | AH16: =SUM(AE16:AH16) -> 0 | AM16: =SUM(AI16:AM16) -> 0 | AP16: =SUM(AN16:AO16) -> 0 | AU16: =SUM(AQ16:AT16) -> 0 | AY16: =F16+J16+S16+AD16+AH16+AM16+AP16+AU16+AV16+AW16+AX16 -> 0
A17: 6 | B17: Ambay, Pepito | F17: =SUM(C17:E17) -> 0 | J17: =SUM(G17:I17) -> 0 | S17: =SUM(K17:R17) -> 0 | AD17: =SUM(T17:AC17) -> 0 | AH17: =SUM(AE17:AH17) -> 0 | AM17: =SUM(AI17:AM17) -> 0 | AP17: =SUM(AN17:AO17) -> 0 | AU17: =SUM(AQ17:AT17) -> 0 | AY17: =F17+J17+S17+AD17+AH17+AM17+AP17+AU17+AV17+AW17+AX17 -> 0
A18: 7 | B18: Chavez, Felicito | F18: =SUM(C18:E18) -> 0 | J18: =SUM(G18:I18) -> 0 | S18: =SUM(K18:R18) -> 0 | AD18: =SUM(T18:AC18) -> 0 | AH18: =SUM(AE18:AH18) -> 0 | AM18: =SUM(AI18:AM18) -> 0 | AP18: =SUM(AN18:AO18) -> 0 | AU18: =SUM(AQ18:AT18) -> 0 | AY18: =F18+J18+S18+AD18+AH18+AM18+AP18+AU18+AV18+AW18+AX18 -> 0
A19: 8 | B19: Zara, Zoilo | F19: =SUM(C19:E19) -> 0 | J19: =SUM(G19:I19) -> 0 | S19: =SUM(K19:R19) -> 0 | AD19: =SUM(T19:AC19) -> 0 | AH19: =SUM(AE19:AH19) -> 0 | AM19: =SUM(AI19:AM19) -> 0 | AP19: =SUM(AN19:AO19) -> 0 | AU19: =SUM(AQ19:AT19) -> 0 | AY19: =F19+J19+S19+AD19+AH19+AM19+AP19+AU19+AV19+AW19+AX19 -> 0
A20: 9 | B20: Pedro, Miranda | F20: =SUM(C20:E20) -> 0 | J20: =SUM(G20:I20) -> 0 | S20: =SUM(K20:R20) -> 0 | AD20: =SUM(T20:AC20) -> 0 | AH20: =SUM(AE20:AH20) -> 0 | AM20: =SUM(AI20:AM20) -> 0 | AP20: =SUM(AN20:AO20) -> 0 | AU20: =SUM(AQ20:AT20) -> 0 | AY20: =F20+J20+S20+AD20+AH20+AM20+AP20+AU20+AV20+AW20+AX20 -> 0
A21: 10 | B21: Matulac, Felino | F21: =SUM(C21:E21) -> 0 | J21: =SUM(G21:I21) -> 0 | S21: =SUM(K21:R21) -> 0 | AD21: =SUM(T21:AC21) -> 0 | AH21: =SUM(AE21:AH21) -> 0 | AM21: =SUM(AI21:AM21) -> 0 | AP21: =SUM(AN21:AO21) -> 0 | AU21: =SUM(AQ21:AT21) -> 0 | AY21: =F21+J21+S21+AD21+AH21+AM21+AP21+AU21+AV21+AW21+AX21 -> 0
A22: 11 | B22: Bindoy, Fausta | F22: =SUM(C22:E22) -> 0 | J22: =SUM(G22:I22) -> 0 | S22: =SUM(K22:R22) -> 0 | AD22: =SUM(T22:AC22) -> 0 | AH22: =SUM(AE22:AH22) -> 0 | AM22: =SUM(AI22:AM22) -> 0 | AP22: =SUM(AN22:AO22) -> 0 | AU22: =SUM(AQ22:AT22) -> 0 | AY22: =F22+J22+S22+AD22+AH22+AM22+AP22+AU22+AV22+AW22+AX22 -> 0
A23: 12 | B23: Perez, Roberto | F23: =SUM(C23:E23) -> 0 | J23: =SUM(G23:I23) -> 0 | S23: =SUM(K23:R23) -> 0 | AD23: =SUM(T23:AC23) -> 0 | AH23: =SUM(AE23:AH23) -> 0 | AM23: =SUM(AI23:AM23) -> 0 | AP23: =SUM(AN23:AO23) -> 0 | AU23: =SUM(AQ23:AT23) -> 0 | AY23: =F23+J23+S23+AD23+AH23+AM23+AP23+AU23+AV23+AW23+AX23 -> 0
... A38: 27 | B38: Buena, Marietta | F38: =SUM(C38:E38) -> 0 | J38: =SUM(G38:I38) -> 0 | S38: =SUM(K38:R38) -> 0 | AD38: =SUM(T38:AC38) -> 0 | AH38: =SUM(AE38:AH38) -> 0 | AM38: =SUM(AI38:AM38) -> 0 | AP38: =SUM(AN38:AO38) -> 0 | AU38: =SUM(AQ38:AT38) -> 0 | AY38: =F38+J38+S38+AD38+AH38+AM38+AP38+AU38+AV38+AW38+AX38 -> 0
A39: GRAND TOTAL
A41: Total area/crop:
A42: Total number of faramers/crop:
A43: Total number of faramers:

Sheet PMQ+Krissy
A2: Province: BATANGAS
A5: No. | B5: MUNICIPALITY | C5: MALE | D5: FEMALE | E5: No. of Farmers | F5: GRAND TOTAL Area (ha) | G5: RICE | O5: CORN | W5: FRUIT VEGETABLES | AU5: LEAFY VEGETABLES | BK5: ROOT VEGETABLES | BW5: FRUIT TREES | CU5: FRUIT TREES | DM5: ROOT CROPS | DY5: SPICES | EO5: LEGUMES | FI5: INDUSTRIAL CROPS | FS5: COCONUT | FU5: SUGARCANE | FW5: BAMBOO
G6: IRRIGATED | I6: RAINFED | K6: UPLAND | M6: TOTAL Area (ha) | O6: YELLOW | Q6: WHITE | S6: GREEN | U6: TOTAL Area (ha) | W6: AMPALAYA | Y6: EGGPLANT | AA6: POLE SITAO | AC6: OKRA | AE6: SQUASH | AG6: TOMATO | AI6: UPO | AK6: PATOLA | AM6: CUCUMBER | AO6: WATERMELON | AQ6: SAYOTE | AS6: SUBTOTAL | AU6: PECHAY | AW6: MUSTARD | AY6: KANGKONG | BA6: PAKCHOI | BC6: LETTUCE | BE6: MALUNGGAY | BG6: SILI TOPS | BI6: SUBTOTAL | BK6: RADISH | BM6: SINGKAMAS | BQ6: SUBTOTAL | BS6: VEGETABLES | BU6: TOTAL Area (ha) | BW6: MANGO | BY6: PAPAYA | CA6: LANZONES | CC6: RAMBUTAN | CE6: TAMARIND | CG6: CITRUS | CI6: GUYABANO | CK6: ATIS | CM6: CHICO | CO6: DRAGON FRUIT | CQ6: JACKFRUIT | CS6: AVOCADO | CU6: DUHAT | CW6: DURIAN | CY6: SANTOL | DA6: GUAVA | DC6: STAR APPLE | DE6: KAMANSI | DG6: CASHEW | DI6: SINIGUELAS | DK6: TOTAL Area (ha) | DM6: SWEET POTATO | DO6: UBE | DQ6: GABI | DS6: TARO | DU6: CASSAVA | DW6: TOTAL Area (ha) | DY6: BLACK PEPPER | EA6: HOT PEPPER | EC6: BELL PEPPER | EE6: GINGER | EG6: GARLIC | EI6: ONION | EK6: TURMERIC | EM6: TOTAL Area (ha) | EO6: PEANUT | EQ6: MUNGBEAN | ES6: SOYBEAN | EU6: PATANI | EW6: SEGUIDILLAS | EY6: COWPEA | FA6: BATAO | FC6: KADYOS | FE6: BAGUIO BEANS | FG6: TOTAL Area (ha) | FI6: COFFEE | FK6: CACAO | FM6: PINEAPPLE | FO6: BANANA | FQ6: TOTAL Area (ha)
G7: NF | H7: Area (ha) | I7: NF | J7: Area (ha) | K7: NF | L7: Area (ha) | M7: NF | N7: Area (ha) | O7: NF | P7: Area (ha) | Q7: NF | R7: Area (ha) | S7: NF | T7: Area (ha) | U7: NF | V7: Area (ha) | W7: NF | X7: Area (ha) | Y7: NF | Z7: Area (ha) | AA7: NF | AB7: Area (ha) | AC7: NF | AD7: Area (ha) | AE7: NF | AF7: Area (ha) | AG7: NF | AH7: Area (ha) | AI7: NF | AJ7: Area (ha) | AK7: NF | AL7: Area (ha) | AM7: NF | AN7: Area (ha) | AO7: NF | AP7: Area (ha) | AQ7: NF | AR7: Area (ha) | AS7: NF | AT7: Area (ha) | AU7: NF | AV7: Area (ha) | AW7: NF | AX7: Area (ha) | AY7: NF | AZ7: Area (ha) | BA7: NF | BB7: Area (ha) | BC7: NF | BD7: Area (ha) | BE7: NF | BF7: Area (ha) | BG7: NF | BH7: Area (ha) | BI7: NF | BJ7: Area (ha) | BK7: NF | BL7: Area (ha) | BM7: NF | BN7: Area (ha) | BO7: NF | BP7: Area (ha) | BQ7: NF | BR7: Area (ha) | BS7: NF | BT7: Area (ha) | BU7: NF | BV7: Area (ha) | BW7: NF | BX7: Area (ha) | BY7: NF | BZ7: Area (ha) | CA7: NF | CB7: Area (ha) | CC7: NF | CD7: Area (ha) | CE7: NF | CF7: Area (ha) | CG7: NF | CH7: Area (ha) | CI7: NF | CJ7: Area (ha) | CK7: NF | CL7: Area (ha) | CM7: NF | CN7: Area (ha) | CO7: NF | CP7: Area (ha) | CQ7: NF | CR7: Area (ha) | CS7: NF | CT7: Area (ha) | CU7: NF | CV7: Area (ha) | CW7: NF | CX7: Area (ha) | CY7: NF | CZ7: Area (ha) | DA7: NF | DB7: Area (ha) | DC7: NF | DD7: Area (ha) | DE7: NF | DF7: Area (ha) | DG7: NF | DH7: Area (ha) | DI7: NF | DJ7: Area (ha) | DK7: NF | DL7: Area (ha) | DM7: NF | DN7: Area (ha) | DO7: NF | DP7: Area (ha) | DQ7: NF | DR7: Area (ha) | DS7: NF | DT7: Area (ha) | DU7: NF | DV7: Area (ha) | DW7: NF | DX7: Area (ha) | DY7: NF | DZ7: Area (ha) | EA7: NF | EB7: Area (ha) | EC7: NF | ED7: Area (ha) | EE7: NF | EF7: Area (ha) | EG7: NF | EH7: Area (ha) | EI7: NF | EJ7: Area (ha) | EK7: NF | EL7: Area (ha) | EM7: NF | EN7: Area (ha) | EO7: NF | EP7: Area (ha) | EQ7: NF | ER7: Area (ha) | ES7: NF | ET7: Area (ha) | EU7: NF | EV7: Area (ha) | EW7: NF | EX7: Area (ha) | EY7: NF | EZ7: Area (ha) | FA7: NF | FB7: Area (ha) | FC7: NF | FD7: Area (ha) | FE7: NF | FF7: Area (ha) | FG7: NF | FH7: Area (ha) | FI7: NF | FJ7: Area (ha) | FK7: NF | FL7: Area (ha) | FM7: NF | FN7: Area (ha) | FO7: NF | FP7: Area (ha) | FQ7: NF | FR7: Area (ha) | FS7: NF | FT7: Area (ha) | FU7: NF | FV7: Area (ha) | FW7: NF | FX7: Area (ha) | FZ7: LEGEND:
A8: 1 | B8: Agoncillo | C8: =#REF! -> #REF! | D8: =#REF! -> #REF! | E8: =C8+D8 -> #REF! | F8: =N8+V8+BV8+DL8+DX8+EN8+FH8+FR8+FT8+FV8+FX8 -> #REF! | G8: =#REF! -> #REF! | H8: =#REF! -> #REF! | I8: =#REF! -> #REF! | J8: =#REF! -> #REF! | K8: =#REF! -> #REF! | L8: =#REF! -> #REF! | M8: =G8+I8+K8 -> #REF! | N8: =H8+J8+L8 -> #REF! | O8: =#REF! -> #REF! | P8: =#REF! -> #REF! | Q8: =#REF! -> #REF! | R8: =#REF! -> #REF! | S8: =#REF! -> #REF! | T8: =#REF! -> #REF! | U8: =O8+Q8+S8 -> #REF! | V8: =P8+R8+T8 -> #REF! | W8: =#REF! -> #REF! | X8: =#REF! -> #REF! | Y8: =#REF! -> #REF! | Z8: =#REF! -> #REF! | AA8: =#REF! -> #REF! | AB8: =#REF! -> #REF! | AC8: =#REF! -> #REF! | AD8: =#REF! -> #REF! | ... AR8: =#REF! -> #REF! | AS8: =W8+Y8+AA8+AC8+AE8+AG8+AI8+AK8+AM8+AO8+AQ8 -> #REF! | AT8: =X8+Z8+AB8+AD8+AF8+AH8+AJ8+AL8+AN8+AP8+AR8 -> #REF! | AU8: =#REF! -> #REF! | AV8: =#REF! -> #REF! | AW8: =#REF! -> #REF! | AX8: =#REF! -> #REF! | AY8: =#REF! -> #REF! | AZ8: =#REF! -> #REF! | BA8: =#REF! -> #REF! | BB8: =#REF! -> #REF! | ... BH8: =#REF! -> #REF! | BI8: =AU8+AW8+AY8+BA8+BC8+BE8+BG8 -> #REF! | BJ8: =AV8+AX8+AZ8+BB8+BD8+BH8+BF8 -> #REF! | BK8: =#REF! -> #REF! | BL8: =#REF! -> #REF! | BM8: =#REF! -> #REF! | BN8: =#REF! -> #REF! | BO8: =#REF! -> #REF! | BP8: =#REF! -> #REF! | BQ8: =BK8+BM8+BO8 -> #REF! | BR8: =BL8+BN8+BP8 -> #REF! | BS8: =#REF! -> #REF! | BT8: =#REF! -> #REF! | BU8: =AS8+BI8+BQ8+BS8 -> #REF! | BV8: =AT8+BJ8+BR8+BT8 -> #REF! | BW8: =#REF! -> #REF! | BX8: =#REF! -> #REF! | BY8: =#REF! -> #REF! | BZ8: =#REF! -> #REF! | CA8: =#REF! -> #REF! | CB8: =#REF! -> #REF! | CC8: =#REF! -> #REF! | CD8: =#REF! -> #REF! | ... DJ8: =#REF! -> #REF! | DK8: =BW8+BY8+CA8+CC8+CE8+CG8+CI8+CK8+CM8+CO8+CQ8+CS8+CU8+CW8+CY8+DA8+DC8+DE8+DG8+DI8 -> #REF! | DL8: =CX8+CV8+CT8+CR8+CP8+CN8+CL8+CJ8+CH8+CF8+CD8+CB8+BZ8+BX8+CZ8+DB8+DD8+DF8+DH8+DJ8 -> #REF! | DM8: =#REF! -> #REF! | DN8: =#REF! -> #REF! | DO8: =#REF! -> #REF! | DP8: =#REF! -> #REF! | DQ8: =#REF! -> #REF! | DR8: =#REF! -> #REF! | DS8: =#REF! -> #REF! | DT8: =#REF! -> #REF! | ... DV8: =#REF! -> #REF! | DW8: =DM8+DO8+DQ8+DS8+DU8 -> #REF! | DX8: =DN8+DP8+DR8+DT8+DV8 -> #REF! | DY8: =#REF! -> #REF! | DZ8: =#REF! -> #REF! | EA8: =#REF! -> #REF! | EB8: =#REF! -> #REF! | EC8: =#REF! -> #REF! | ED8: =#REF! -> #REF! | EE8: =#REF! -> #REF! | EF8: =#REF! -> #REF! | ... EL8: =#REF! -> #REF! | EM8: =DY8+EA8+EC8+EE8+EG8+EI8+EK8 -> #REF! | EN8: =DZ8+EB8+ED8+EF8+EH8+EJ8+EL8 -> #REF! | EO8: =#REF! -> #REF! | EP8: =#REF! -> #REF! | EQ8: =#REF! -> #REF! | ER8: =#REF! -> #REF! | ES8: =#REF! -> #REF! | ET8: =#REF! -> #REF! | EU8: =#REF! -> #REF! | EV8: =#REF! -> #REF! | ... FF8: =#REF! -> #REF! | FG8: =EO8+EQ8+ES8+EU8+EW8+EY8+FA8+FC8+FE8 -> #REF! | FH8: =FD8+FB8+EZ8+EX8+EV8+ET8+ER8+EP8+FF8 -> #REF! | FI8: =#REF! -> #REF! | FJ8: =#REF! -> #REF! | FK8: =#REF! -> #REF! | FL8: =#REF! -> #REF! | FM8: =#REF! -> #REF! | FN8: =#REF! -> #REF! | FO8: =#REF! -> #REF! | FP8: =#REF! -> #REF! | FQ8: =FI8+FK8+FM8+FO8 -> #REF! | FR8: =FJ8+FL8+FN8+FP8 -> #REF! | FS8: 107 | FT8: 166 | FW8: 345 | FX8: 7 | GA8: 2013 Data
A9: 2 | B9: Alitagtag | C9: =Form!C46 -> 1886 | D9: =Form!D46 -> 1110 | E9: =C9+D9 -> 2996 | F9: =N9+V9+BV9+DL9+DX9+EN9+FH9+FR9+FT9+FV9+FX9 -> #REF! | G9: =Form!H46 -> 0 | H9: =Form!I46 -> 0 | I9: =Form!J46 -> 0 | J9: =Form!K46 -> 0 | K9: =Form!L46 -> 0 | L9: =Form!M46 -> 0 | M9: =G9+I9+K9 -> 0 | N9: =H9+J9+L9 -> 0 | O9: =Form!P46 -> 21 | P9: =Form!Q46 -> 17.05 | Q9: =Form!R46 -> 435 | R9: =Form!S46 -> 268.34 | S9: =Form!T46 -> 0 | T9: =Form!U46 -> 0 | U9: =O9+Q9+S9 -> 456 | V9: =P9+R9+T9 -> 285.39 | W9: =Form!W46 -> 313.225 | X9: =Form!X46 -> 116.952 | Y9: =Form!Y46 -> 122 | Z9: =Form!Z46 -> 74.13 | AA9: =Form!AA46 -> 331 | AB9: =Form!AB46 -> 84.288 | AC9: =Form!AC46 -> 137.3 | AD9: =Form!AD46 -> 37.577 | ... AR9: =Form!AR46 -> 0.15 | AS9: =W9+Y9+AA9+AC9+AE9+AG9+AI9+AK9+AM9+AO9+AQ9 -> 1488.075 | AT9: =X9+Z9+AB9+AD9+AF9+AH9+AJ9+AL9+AN9+AP9+AR9 -> 503.189 | AU9: =Form!AT46 -> 272 | AV9: =Form!AU46 -> 178.1237 | AW9: =Form!#REF! -> #REF! | AX9: =Form!#REF! -> #REF! | AY9: =Form!#REF! -> #REF! | AZ9: =Form!#REF! -> #REF! | BA9: =Form!#REF! -> #REF! | BB9: =Form!#REF! -> #REF! | BC9: =Form!#REF! -> #REF! | BD9: =Form!#REF! -> #REF! | ... BH9: =Form!#REF! -> #REF! | BI9: =AU9+AW9+AY9+BA9+BC9+BE9+BG9 -> #REF! | BJ9: =AV9+AX9+AZ9+BB9+BD9+BH9+BF9 -> #REF! | BK9: =Form!BI46 -> 0 | BL9: =Form!BJ46 -> 0 | BM9: =Form!BK46 -> 0 | BN9: =Form!BL46 -> 0 | BO9: =Form!#REF! -> #REF! | BP9: =Form!#REF! -> #REF! | BQ9: =BK9+BM9+BO9 -> #REF! | BR9: =BL9+BN9+BP9 -> #REF! | BU9: =AS9+BI9+BQ9+BS9 -> #REF! | BV9: =AT9+BJ9+BR9+BT9 -> #REF! | BW9: =Form!BO46 -> 54 | BX9: =Form!#REF! -> #REF! | BY9: =Form!#REF! -> #REF! | BZ9: =Form!#REF! -> #REF! | CA9: =Form!#REF! -> #REF! | CB9: =Form!#REF! -> #REF! | CC9: =Form!#REF! -> #REF! | CD9: =Form!#REF! -> #REF! | CE9: =Form!#REF! -> #REF! | ... CN9: =Form!#REF! -> #REF! | CO9: =Form!CG46 -> 26 | CP9: =Form!CH46 -> 12.615 | CQ9: =Form!CI46 -> 71 | CR9: =Form!CJ46 -> 13.409 | CS9: =Form!CK46 -> 180.05 | CT9: =Form!CL46 -> 65.5165 | CU9: =Form!CM46 -> 0.05 | CV9: =Form!CN46 -> 0 | ... DJ9: =Form!DB46 -> 0 | DK9: =BW9+BY9+CA9+CC9+CE9+CG9+CI9+CK9+CM9+CO9+CQ9+CS9+CU9+CW9+CY9+DA9+DC9+DE9+DG9+DI9 -> #REF! | DL9: =CX9+CV9+CT9+CR9+CP9+CN9+CL9+CJ9+CH9+CF9+CD9+CB9+BZ9+BX9+CZ9+DB9+DD9+DF9+DH9+DJ9 -> #REF! | DM9: =Form!DD46 -> 209 | DN9: =Form!DE46 -> 41.6093 | DO9: =Form!DF46 -> 5 | DP9: =Form!DG46 -> 0.82 | DQ9: =Form!DH46 -> 74 | DR9: =Form!DI46 -> 11.66 | DS9: =Form!DJ46 -> 1 | DT9: =Form!DK46 -> 10 | ... DV9: =Form!DM46 -> 85.957 | DW9: =DM9+DO9+DQ9+DS9+DU9 -> 539 | DX9: =DN9+DP9+DR9+DT9+DV9 -> 150.0463 | DY9: =Form!DO46 -> 6 | DZ9: =Form!DP46 -> 0.41 | EA9: =Form!DQ46 -> 296 | EB9: =Form!DR46 -> 88.322 | EC9: =Form!DS46 -> 2 | ED9: =Form!DT46 -> 0.1 | EE9: =Form!DU46 -> 136 | EF9: =Form!DV46 -> 21.798 | ... EL9: =Form!EB46 -> 0 | EM9: =DY9+EA9+EC9+EE9+EG9+EI9+EK9 -> 449 | EN9: =DZ9+EB9+ED9+EF9+EH9+EJ9+EL9 -> 114.18 | EO9: =Form!ED46 -> 28 | EP9: =Form!EE46 -> 6.38 | EQ9: =Form!EF46 -> 8 | ER9: =Form!EG46 -> 5 | ES9: =Form!EH46 -> 0 | ET9: =Form!EI46 -> 0 | EU9: =Form!EJ46 -> 227 | EV9: =Form!EK46 -> 34.141 | ... FF9: =Form!EU46 -> 8.785 | FG9: =EO9+EQ9+ES9+EU9+EW9+EY9+FA9+FC9+FE9 -> 1129.46 | FH9: =FD9+FB9+EZ9+EX9+EV9+ET9+ER9+EP9+FF9 -> 258.897 | FI9: =Form!EW46 -> 13 | FJ9: =Form!EX46 -> 3.29 | FK9: =Form!EY46 -> 82 | FL9: =Form!EZ46 -> 21.362 | FM9: =Form!FA46 -> 52 | FN9: =Form!FB46 -> 11.43 | FO9: =Form!FC46 -> 1280 | FP9: =Form!FD46 -> 494.8578 | FQ9: =FI9+FK9+FM9+FO9 -> 1427 | FR9: =FJ9+FL9+FN9+FP9 -> 530.9398 | FS9: 117 | FT9: 133 | FV9: 800 | FW9: 60 | FX9: 21.5 | GA9: PCA Data
A10: 3 | B10: Balayan | C10: =#REF! -> #REF! | D10: =#REF! -> #REF! | E10: =C10+D10 -> #REF! | F10: =N10+V10+BV10+DL10+DX10+EN10+FH10+FR10+FT10+FV10+FX10 -> #REF! | G10: =#REF! -> #REF! | H10: =#REF! -> #REF! | I10: =#REF! -> #REF! | J10: =#REF! -> #REF! | K10: =#REF! -> #REF! | L10: =#REF! -> #REF! | M10: =G10+I10+K10 -> #REF! | N10: =H10+J10+L10 -> #REF! | O10: =#REF! -> #REF! | P10: =#REF! -> #REF! | Q10: =#REF! -> #REF! | R10: =#REF! -> #REF! | S10: =#REF! -> #REF! | T10: =#REF! -> #REF! | U10: =O10+Q10+S10 -> #REF! | V10: =P10+R10+T10 -> #REF! | W10: =#REF! -> #REF! | X10: =#REF! -> #REF! | Y10: =#REF! -> #REF! | Z10: =#REF! -> #REF! | AA10: =#REF! -> #REF! | AB10: =#REF! -> #REF! | AC10: =#REF! -> #REF! | AD10: =#REF! -> #REF! | ... AR10: =#REF! -> #REF! | AS10: =W10+Y10+AA10+AC10+AE10+AG10+AI10+AK10+AM10+AO10+AQ10 -> #REF! | AT10: =X10+Z10+AB10+AD10+AF10+AH10+AJ10+AL10+AN10+AP10+AR10 -> #REF! | AU10: =#REF! -> #REF! | AV10: =#REF! -> #REF! | AW10: =#REF! -> #REF! | AX10: =#REF! -> #REF! | AY10: =#REF! -> #REF! | AZ10: =#REF! -> #REF! | BA10: =#REF! -> #REF! | BB10: =#REF! -> #REF! | ... BH10: =#REF! -> #REF! | BI10: =AU10+AW10+AY10+BA10+BC10+BE10+BG10 -> #REF! | BJ10: =AV10+AX10+AZ10+BB10+BD10+BH10+BF10 -> #REF! | BK10: =#REF! -> #REF! | BL10: =#REF! -> #REF! | BM10: =#REF! -> #REF! | BN10: =#REF! -> #REF! | BO10: =#REF! -> #REF! | BP10: =#REF! -> #REF! | BQ10: =BK10+BM10+BO10 -> #REF! | BR10: =BL10+BN10+BP10 -> #REF! | BS10: =#REF! -> #REF! | BT10: =#REF! -> #REF! | BU10: =AS10+BI10+BQ10+BS10 -> #REF! | BV10: =AT10+BJ10+BR10+BT10 -> #REF! | BW10: =#REF! -> #REF! | BX10: =#REF! -> #REF! | BY10: =#REF! -> #REF! | BZ10: =#REF! -> #REF! | CA10: =#REF! -> #REF! | CB10: =#REF! -> #REF! | CC10: =#REF! -> #REF! | CD10: =#REF! -> #REF! | ... DJ10: =#REF! -> #REF! | DK10: =BW10+BY10+CA10+CC10+CE10+CG10+CI10+CK10+CM10+CO10+CQ10+CS10+CU10+CW10+CY10+DA10+DC10+DE10+DG10+DI10 -> #REF! | DL10: =CX10+CV10+CT10+CR10+CP10+CN10+CL10+CJ10+CH10+CF10+CD10+CB10+BZ10+BX10+CZ10+DB10+DD10+DF10+DH10+DJ10 -> #REF! | DM10: =#REF! -> #REF! | DN10: =#REF! -> #REF! | DO10: =#REF! -> #REF! | DP10: =#REF! -> #REF! | DQ10: =#REF! -> #REF! | DR10: =#REF! -> #REF! | DS10: =#REF! -> #REF! | DT10: =#REF! -> #REF! | ... DV10: =#REF! -> #REF! | DW10: =DM10+DO10+DQ10+DS10+DU10 -> #REF! | DX10: =DN10+DP10+DR10+DT10+DV10 -> #REF! | DY10: =#REF! -> #REF! | DZ10: =#REF! -> #REF! | EA10: =#REF! -> #REF! | EB10: =#REF! -> #REF! | EC10: =#REF! -> #REF! | ED10: =#REF! -> #REF! | EE10: =#REF! -> #REF! | EF10: =#REF! -> #REF! | ... EL10: =#REF! -> #REF! | EM10: =DY10+EA10+EC10+EE10+EG10+EI10+EK10 -> #REF! | EN10: =DZ10+EB10+ED10+EF10+EH10+EJ10+EL10 -> #REF! | EO10: =#REF! -> #REF! | EP10: =#REF! -> #REF! | EQ10: =#REF! -> #REF! | ER10: =#REF! -> #REF! | ES10: =#REF! -> #REF! | ET10: =#REF! -> #REF! | EU10: =#REF! -> #REF! | EV10: =#REF! -> #REF! | ... FF10: =#REF! -> #REF! | FG10: =EO10+EQ10+ES10+EU10+EW10+EY10+FA10+FC10+FE10 -> #REF! | FH10: =FD10+FB10+EZ10+EX10+EV10+ET10+ER10+EP10+FF10 -> #REF! | FI10: =#REF! -> #REF! | FJ10: =#REF! -> #REF! | FK10: =#REF! -> #REF! | FL10: =#REF! -> #REF! | FM10: =#REF! -> #REF! | FN10: =#REF! -> #REF! | FO10: =#REF! -> #REF! | FP10: =#REF! -> #REF! | FQ10: =FI10+FK10+FM10+FO10 -> #REF! | FR10: =FJ10+FL10+FN10+FP10 -> #REF! | FS10: 87 | FT10: 91.5 | FV10: 4901 | FW10: =#REF! -> #REF! | FX10: =#REF! -> #REF! | GA10: SRA Data
A11: 4 | B11: Balete | C11: =#REF! -> #REF! | D11: =#REF! -> #REF! | E11: =C11+D11 -> #REF! | F11: =N11+V11+BV11+DL11+DX11+EN11+FH11+FR11+FT11+FV11+FX11 -> #REF! | G11: =#REF! -> #REF! | H11: =#REF! -> #REF! | I11: =#REF! -> #REF! | J11: =#REF! -> #REF! | K11: =#REF! -> #REF! | L11: =#REF! -> #REF! | M11: =G11+I11+K11 -> #REF! | N11: =H11+J11+L11 -> #REF! | O11: =#REF! -> #REF! | P11: =#REF! -> #REF! | Q11: =#REF! -> #REF! | R11: =#REF! -> #REF! | S11: =#REF! -> #REF! | T11: =#REF! -> #REF! | U11: =O11+Q11+S11 -> #REF! | V11: =P11+R11+T11 -> #REF! | W11: =#REF! -> #REF! | X11: =#REF! -> #REF! | Y11: =#REF! -> #REF! | Z11: =#REF! -> #REF! | AA11: =#REF! -> #REF! | AB11: =#REF! -> #REF! | AC11: =#REF! -> #REF! | AD11: =#REF! -> #REF! | ... AR11: =#REF! -> #REF! | AS11: =W11+Y11+AA11+AC11+AE11+AG11+AI11+AK11+AM11+AO11+AQ11 -> #REF! | AT11: =X11+Z11+AB11+AD11+AF11+AH11+AJ11+AL11+AN11+AP11+AR11 -> #REF! | AU11: =#REF! -> #REF! | AV11: =#REF! -> #REF! | AW11: =#REF! -> #REF! | AX11: =#REF! -> #REF! | AY11: =#REF! -> #REF! | AZ11: =#REF! -> #REF! | BA11: =#REF! -> #REF! | BB11: =#REF! -> #REF! | ... BH11: =#REF! -> #REF! | BI11: =AU11+AW11+AY11+BA11+BC11+BE11+BG11 -> #REF! | BJ11: =AV11+AX11+AZ11+BB11+BD11+BH11+BF11 -> #REF! | BK11: =#REF! -> #REF! | BL11: =#REF! -> #REF! | BM11: =#REF! -> #REF! | BN11: =#REF! -> #REF! | BO11: =#REF! -> #REF! | BP11: =#REF! -> #REF! | BQ11: =BK11+BM11+BO11 -> #REF! | BR11: =BL11+BN11+BP11 -> #REF! | BS11: =#REF! -> #REF! | BT11: =#REF! -> #REF! | BU11: =AS11+BI11+BQ11+BS11 -> #REF! | BV11: =AT11+BJ11+BR11+BT11 -> #REF! | BW11: =#REF! -> #REF! | BX11: =#REF! -> #REF! | BY11: =#REF! -> #REF! | BZ11: =#REF! -> #REF! | CA11: =#REF! -> #REF! | CB11: =#REF! -> #REF! | CC11: =#REF! -> #REF! | CD11: =#REF! -> #REF! | ... DJ11: =#REF! -> #REF! | DK11: =BW11+BY11+CA11+CC11+CE11+CG11+CI11+CK11+CM11+CO11+CQ11+CS11+CU11+CW11+CY11+DA11+DC11+DE11+DG11+DI11 -> #REF! | DL11: =CX11+CV11+CT11+CR11+CP11+CN11+CL11+CJ11+CH11+CF11+CD11+CB11+BZ11+BX11+CZ11+DB11+DD11+DF11+DH11+DJ11 -> #REF! | DM11: =#REF! -> #REF! | DN11: =#REF! -> #REF! | DO11: =#REF! -> #REF! | DP11: =#REF! -> #REF! | DQ11: =#REF! -> #REF! | DR11: =#REF! -> #REF! | DS11: =#REF! -> #REF! | DT11: =#REF! -> #REF! | ... DV11: =#REF! -> #REF! | DW11: =DM11+DO11+DQ11+DS11+DU11 -> #REF! | DX11: =DN11+DP11+DR11+DT11+DV11 -> #REF! | DY11: =#REF! -> #REF! | DZ11: =#REF! -> #REF! | EA11: =#REF! -> #REF! | EB11: =#REF! -> #REF! | EC11: =#REF! -> #REF! | ED11: =#REF! -> #REF! | EE11: =#REF! -> #REF! | EF11: =#REF! -> #REF! | ... EL11: =#REF! -> #REF! | EM11: =DY11+EA11+EC11+EE11+EG11+EI11+EK11 -> #REF! | EN11: =DZ11+EB11+ED11+EF11+EH11+EJ11+EL11 -> #REF! | EO11: =#REF! -> #REF! | EP11: =#REF! -> #REF! | EQ11: =#REF! -> #REF! | ER11: =#REF! -> #REF! | ES11: =#REF! -> #REF! | ET11: =#REF! -> #REF! | EU11: =#REF! -> #REF! | EV11: =#REF! -> #REF! | ... FF11: =#REF! -> #REF! | FG11: =EO11+EQ11+ES11+EU11+EW11+EY11+FA11+FC11+FE11 -> #REF! | FH11: =FD11+FB11+EZ11+EX11+EV11+ET11+ER11+EP11+FF11 -> #REF! | FI11: =#REF! -> #REF! | FJ11: =#REF! -> #REF! | FK11: =#REF! -> #REF! | FL11: =#REF! -> #REF! | FM11: =#REF! -> #REF! | FN11: =#REF! -> #REF! | FO11: =#REF! -> #REF! | FP11: =#REF! -> #REF! | FQ11: =FI11+FK11+FM11+FO11 -> #REF! | FR11: =FJ11+FL11+FN11+FP11 -> #REF! | FS11: 681 | FT11: 610 | FU11: =#REF! -> #REF! | FV11: =#REF! -> #REF! | FW11: =#REF! -> #REF! | FX11: =#REF! -> #REF! | GA11: Data after validation
A12: 5 | B12: Batangas City - no data | E12: =M12+U12+BU12+DK12+DW12+EM12+FG12+FQ12+FS12+FU12+FW12 -> 3719 | F12: =N12+V12+BV12+DL12+DX12+EN12+FH12+FR12+FT12+FV12+FX12 -> 5759.75 | K12: 20 | L12: 7 | M12: =G12+I12+K12 -> 20 | N12: =H12+J12+L12 -> 7 | O12: 150 | P12: 375 | S12: 150 | T12: 300 | U12: =O12+Q12+S12 -> 300 | V12: =P12+R12+T12 -> 675 | W12: 209 | X12: 300 | AS12: =W12+Y12+AA12+AC12+AE12+AG12+AI12+AK12+AM12+AO12+AQ12 -> 209 | AT12: =X12+Z12+AB12+AD12+AF12+AH12+AJ12+AL12+AN12+AP12+AR12 -> 300 | BI12: =AU12+AW12+AY12+BA12+BC12+BE12+BG12 -> 0 | BJ12: =AV12+AX12+AZ12+BB12+BD12+BH12+BF12 -> 0 | BQ12: =BK12+BM12+BO12 -> 0 | BR12: =BL12+BN12+BP12 -> 0 | BU12: =AS12+BI12+BQ12+BS12 -> 209 | BV12: =AT12+BJ12+BR12+BT12 -> 300 | BW12: 988 | BX12: 1400 | CC12: 64 | CD12: 6 | CG12: 50 | CH12: 38 | CM12: 150 | CN12: 90 | CY12: 75 | CZ12: 46 | DK12: =BW12+BY12+CA12+CC12+CE12+CG12+CI12+CK12+CM12+CO12+CQ12+CS12+CU12+CW12+CY12+DA12+DC12+DE12+DG12+DI12+1040 -> 2367 | DL12: =CX12+CV12+CT12+CR12+CP12+CN12+CL12+CJ12+CH12+CF12+CD12+CB12+BZ12+BX12+CZ12+DB12+DD12+DF12+DH12+DJ12+2400 -> 3980 | DM12: 125 | DN12: 100 | DU12: 85 | DV12: 150 | DW12: =DM12+DO12+DQ12+DS12+DU12 -> 210 | DX12: =DN12+DP12+DR12+DT12+DV12 -> 250 | EM12: =DY12+EA12+EC12+EE12+EG12+EI12+EK12 -> 0 | EN12: =DZ12+EB12+ED12+EF12+EH12+EJ12+EL12 -> 0 | EO12: 30 | EP12: 68.75 | FG12: =EO12+EQ12+ES12+EU12+EW12+EY12+FA12+FC12+FE12 -> 30 | FH12: =FD12+FB12+EZ12+EX12+EV12+ET12+ER12+EP12+FF12 -> 68.75 | FI12: 37 | FJ12: 25 | FO12: 500 | FP12: 328 | FQ12: =FI12+FK12+FM12+FO12 -> 537 | FR12: =FJ12+FL12+FN12+FP12 -> 353 | FS12: 46 | FT12: 82 | FV12: 44 | GA12: PMQ
A13: 6 | B13: Bauan | C13: =#REF! -> #REF! | D13: =#REF! -> #REF! | E13: =C13+D13 -> #REF! | F13: =N13+V13+BV13+DL13+DX13+EN13+FH13+FR13+FT13+FV13+FX13 -> #REF! | G13: =#REF! -> #REF! | H13: =#REF! -> #REF! | I13: =#REF! -> #REF! | J13: =#REF! -> #REF! | K13: =#REF! -> #REF! | L13: =#REF! -> #REF! | M13: =G13+I13+K13 -> #REF! | N13: =H13+J13+L13 -> #REF! | O13: =#REF! -> #REF! | P13: =#REF! -> #REF! | Q13: =#REF! -> #REF! | R13: =#REF! -> #REF! | S13: =#REF! -> #REF! | T13: =#REF! -> #REF! | U13: =O13+Q13+S13 -> #REF! | V13: =P13+R13+T13 -> #REF! | W13: =#REF! -> #REF! | X13: =#REF! -> #REF! | Y13: =#REF! -> #REF! | Z13: =#REF! -> #REF! | AA13: =#REF! -> #REF! | AB13: =#REF! -> #REF! | AC13: =#REF! -> #REF! | AD13: =#REF! -> #REF! | ... AR13: =#REF! -> #REF! | AS13: =W13+Y13+AA13+AC13+AE13+AG13+AI13+AK13+AM13+AO13+AQ13 -> #REF! | AT13: =X13+Z13+AB13+AD13+AF13+AH13+AJ13+AL13+AN13+AP13+AR13 -> #REF! | AU13: =#REF! -> #REF! | AV13: =#REF! -> #REF! | AW13: =#REF! -> #REF! | AX13: =#REF! -> #REF! | AY13: =#REF! -> #REF! | AZ13: =#REF! -> #REF! | BA13: =#REF! -> #REF! | BB13: =#REF! -> #REF! | ... BH13: =#REF! -> #REF! | BI13: =AU13+AW13+AY13+BA13+BC13+BE13+BG13 -> #REF! | BJ13: =AV13+AX13+AZ13+BB13+BD13+BH13+BF13 -> #REF! | BK13: =#REF! -> #REF! | BL13: =#REF! -> #REF! | BM13: =#REF! -> #REF! | BN13: =#REF! -> #REF! | BO13: =#REF! -> #REF! | BP13: =#REF! -> #REF! | BQ13: =BK13+BM13+BO13 -> #REF! | BR13: =BL13+BN13+BP13 -> #REF! | BS13: =#REF! -> #REF! | BT13: =#REF! -> #REF! | BU13: =AS13+BI13+BQ13+BS13 -> #REF! | BV13: =AT13+BJ13+BR13+BT13 -> #REF! | BW13: =#REF! -> #REF! | BX13: =#REF! -> #REF! | BY13: =#REF! -> #REF! | BZ13: =#REF! -> #REF! | CA13: =#REF! -> #REF! | CB13: =#REF! -> #REF! | CC13: =#REF! -> #REF! | CD13: =#REF! -> #REF! | ... DJ13: =#REF! -> #REF! | DK13: =BW13+BY13+CA13+CC13+CE13+CG13+CI13+CK13+CM13+CO13+CQ13+CS13+CU13+CW13+CY13+DA13+DC13+DE13+DG13+DI13 -> #REF! | DL13: =CX13+CV13+CT13+CR13+CP13+CN13+CL13+CJ13+CH13+CF13+CD13+CB13+BZ13+BX13+CZ13+DB13+DD13+DF13+DH13+DJ13 -> #REF! | DM13: =#REF! -> #REF! | DN13: =#REF! -> #REF! | DO13: =#REF! -> #REF! | DP13: =#REF! -> #REF! | DQ13: =#REF! -> #REF! | DR13: =#REF! -> #REF! | DS13: =#REF! -> #REF! | DT13: =#REF! -> #REF! | ... DV13: =#REF! -> #REF! | DW13: =DM13+DO13+DQ13+DS13+DU13 -> #REF! | DX13: =DN13+DP13+DR13+DT13+DV13 -> #REF! | DY13: =#REF! -> #REF! | DZ13: =#REF! -> #REF! | EA13: =#REF! -> #REF! | EB13: =#REF! -> #REF! | EC13: =#REF! -> #REF! | ED13: =#REF! -> #REF! | EE13: =#REF! -> #REF! | EF13: =#REF! -> #REF! | ... EL13: =#REF! -> #REF! | EM13: =DY13+EA13+EC13+EE13+EG13+EI13+EK13 -> #REF! | EN13: =DZ13+EB13+ED13+EF13+EH13+EJ13+EL13 -> #REF! | EO13: =#REF! -> #REF! | EP13: =#REF! -> #REF! | EQ13: =#REF! -> #REF! | ER13: =#REF! -> #REF! | ES13: =#REF! -> #REF! | ET13: =#REF! -> #REF! | EU13: =#REF! -> #REF! | EV13: =#REF! -> #REF! | ... FF13: =#REF! -> #REF! | FG13: =EO13+EQ13+ES13+EU13+EW13+EY13+FA13+FC13+FE13 -> #REF! | FH13: =FD13+FB13+EZ13+EX13+EV13+ET13+ER13+EP13+FF13 -> #REF! | FI13: =#REF! -> #REF! | FJ13: =#REF! -> #REF! | FK13: =#REF! -> #REF! | FL13: =#REF! -> #REF! | FM13: =#REF! -> #REF! | FN13: =#REF! -> #REF! | FO13: =#REF! -> #REF! | FP13: =#REF! -> #REF! | FQ13: =FI13+FK13+FM13+FO13 -> #REF! | FR13: =FJ13+FL13+FN13+FP13 -> #REF! | FS13: 128 | FT13: 117.04 | FU13: =#REF! -> #REF! | FV13: 150 | FW13: =#REF! -> #REF! | FX13: =#REF! -> #REF!
A14: 7 | B14: Calaca | C14: =#REF! -> #REF! | D14: =#REF! -> #REF! | E14: =C14+D14 -> #REF! | F14: =N14+V14+BV14+DL14+DX14+EN14+FH14+FR14+FT14+FV14+FX14 -> #REF! | G14: =#REF! -> #REF! | H14: =#REF! -> #REF! | I14: =#REF! -> #REF! | J14: =#REF! -> #REF! | K14: =#REF! -> #REF! | L14: =#REF! -> #REF! | M14: =G14+I14+K14 -> #REF! | N14: =H14+J14+L14 -> #REF! | O14: =#REF! -> #REF! | P14: =#REF! -> #REF! | Q14: =#REF! -> #REF! | R14: =#REF! -> #REF! | S14: =#REF! -> #REF! | T14: =#REF! -> #REF! | U14: =O14+Q14+S14 -> #REF! | V14: =P14+R14+T14 -> #REF! | W14: =#REF! -> #REF! | X14: =#REF! -> #REF! | Y14: =#REF! -> #REF! | Z14: =#REF! -> #REF! | AA14: =#REF! -> #REF! | AB14: =#REF! -> #REF! | AC14: =#REF! -> #REF! | AD14: =#REF! -> #REF! | ... AR14: =#REF! -> #REF! | AS14: =W14+Y14+AA14+AC14+AE14+AG14+AI14+AK14+AM14+AO14+AQ14 -> #REF! | AT14: =X14+Z14+AB14+AD14+AF14+AH14+AJ14+AL14+AN14+AP14+AR14 -> #REF! | AU14: =#REF! -> #REF! | AV14: =#REF! -> #REF! | AW14: =#REF! -> #REF! | AX14: =#REF! -> #REF! | AY14: =#REF! -> #REF! | AZ14: =#REF! -> #REF! | BA14: =#REF! -> #REF! | BB14: =#REF! -> #REF! | ... BH14: =#REF! -> #REF! | BI14: =AU14+AW14+AY14+BA14+BC14+BE14+BG14 -> #REF! | BJ14: =AV14+AX14+AZ14+BB14+BD14+BH14+BF14 -> #REF! | BK14: =#REF! -> #REF! | BL14: =#REF! -> #REF! | BM14: =#REF! -> #REF! | BN14: =#REF! -> #REF! | BO14: =#REF! -> #REF! | BP14: =#REF! -> #REF! | BQ14: =BK14+BM14+BO14 -> #REF! | BR14: =BL14+BN14+BP14 -> #REF! | BS14: =#REF! -> #REF! | BT14: =#REF! -> #REF! | BU14: =AS14+BI14+BQ14+BS14 -> #REF! | BV14: =AT14+BJ14+BR14+BT14 -> #REF! | BW14: =#REF! -> #REF! | BX14: 27.18 | BY14: =#REF! -> #REF! | BZ14: =#REF! -> #REF! | CA14: =#REF! -> #REF! | CB14: =#REF! -> #REF! | CC14: =#REF! -> #REF! | CD14: =#REF! -> #REF! | CE14: =#REF! -> #REF! | CF14: =#REF! -> #REF! | ... DJ14: =#REF! -> #REF! | DK14: =BW14+BY14+CA14+CC14+CE14+CG14+CI14+CK14+CM14+CO14+CQ14+CS14+CU14+CW14+CY14+DA14+DC14+DE14+DG14+DI14 -> #REF! | DL14: =CX14+CV14+CT14+CR14+CP14+CN14+CL14+CJ14+CH14+CF14+CD14+CB14+BZ14+BX14+CZ14+DB14+DD14+DF14+DH14+DJ14 -> #REF! | DM14: =#REF! -> #REF! | DN14: =#REF! -> #REF! | DO14: =#REF! -> #REF! | DP14: =#REF! -> #REF! | DQ14: =#REF! -> #REF! | DR14: =#REF! -> #REF! | DS14: =#REF! -> #REF! | DT14: =#REF! -> #REF! | ... DV14: =#REF! -> #REF! | DW14: =DM14+DO14+DQ14+DS14+DU14 -> #REF! | DX14: =DN14+DP14+DR14+DT14+DV14 -> #REF! | DY14: =#REF! -> #REF! | DZ14: =#REF! -> #REF! | EA14: =#REF! -> #REF! | EB14: =#REF! -> #REF! | EC14: =#REF! -> #REF! | ED14: =#REF! -> #REF! | EE14: =#REF! -> #REF! | EF14: =#REF! -> #REF! | ... EL14: =#REF! -> #REF! | EM14: =DY14+EA14+EC14+EE14+EG14+EI14+EK14 -> #REF! | EN14: =DZ14+EB14+ED14+EF14+EH14+EJ14+EL14 -> #REF! | EO14: =#REF! -> #REF! | EP14: =#REF! -> #REF! | EQ14: =#REF! -> #REF! | ER14: =#REF! -> #REF! | ES14: =#REF! -> #REF! | ET14: =#REF! -> #REF! | EU14: =#REF! -> #REF! | EV14: =#REF! -> #REF! | ... FF14: =#REF! -> #REF! | FG14: =EO14+EQ14+ES14+EU14+EW14+EY14+FA14+FC14+FE14 -> #REF! | FH14: =FD14+FB14+EZ14+EX14+EV14+ET14+ER14+EP14+FF14 -> #REF! | FI14: =#REF! -> #REF! | FJ14: =#REF! -> #REF! | FK14: =#REF! -> #REF! | FL14: =#REF! -> #REF! | FM14: =#REF! -> #REF! | FN14: =#REF! -> #REF! | FO14: =#REF! -> #REF! | FP14: =#REF! -> #REF! | FQ14: =FI14+FK14+FM14+FO14 -> #REF! | FR14: =FJ14+FL14+FN14+FP14 -> #REF! | FS14: 1395 | FT14: 2616 | FU14: =#REF! -> #REF! | FV14: 1961 | FW14: =#REF! -> #REF! | FX14: =#REF! -> #REF!
A15: 8 | B15: Calatagan | C15: =#REF! -> #REF! | D15: =#REF! -> #REF! | E15: =C15+D15 -> #REF! | F15: =N15+V15+BV15+DL15+DX15+EN15+FH15+FR15+FT15+FV15+FX15 -> #REF! | G15: 134 | H15: 94 | I15: 145 | J15: 62.86 | K15: 322 | L15: 197.78 | M15: =G15+I15+K15 -> 601 | N15: =H15+J15+L15 -> 354.64 | O15: =#REF! -> #REF! | P15: =#REF! -> #REF! | Q15: =#REF! -> #REF! | R15: =#REF! -> #REF! | S15: =#REF! -> #REF! | T15: =#REF! -> #REF! | U15: =O15+Q15+S15 -> #REF! | V15: =P15+R15+T15 -> #REF! | W15: =#REF! -> #REF! | X15: =#REF! -> #REF! | Y15: =#REF! -> #REF! | Z15: =#REF! -> #REF! | AA15: =#REF! -> #REF! | AB15: =#REF! -> #REF! | AC15: =#REF! -> #REF! | AD15: =#REF! -> #REF! | ... AR15: =#REF! -> #REF! | AS15: =W15+Y15+AA15+AC15+AE15+AG15+AI15+AK15+AM15+AO15+AQ15 -> #REF! | AT15: =X15+Z15+AB15+AD15+AF15+AH15+AJ15+AL15+AN15+AP15+AR15 -> #REF! | AU15: =#REF! -> #REF! | AV15: =#REF! -> #REF! | AW15: =#REF! -> #REF! | AX15: =#REF! -> #REF! | AY15: =#REF! -> #REF! | AZ15: =#REF! -> #REF! | BA15: =#REF! -> #REF! | BB15: =#REF! -> #REF! | ... BH15: =#REF! -> #REF! | BI15: =AU15+AW15+AY15+BA15+BC15+BE15+BG15 -> #REF! | BJ15: =AV15+AX15+AZ15+BB15+BD15+BH15+BF15 -> #REF! | BK15: =#REF! -> #REF! | BL15: =#REF! -> #REF! | BM15: =#REF! -> #REF! | BN15: =#REF! -> #REF! | BO15: =#REF! -> #REF! | BP15: =#REF! -> #REF! | BQ15: =BK15+BM15+BO15 -> #REF! | BR15: =BL15+BN15+BP15 -> #REF! | BS15: =#REF! -> #REF! | BT15: =#REF! -> #REF! | BU15: =AS15+BI15+BQ15+BS15 -> #REF! | BV15: =AT15+BJ15+BR15+BT15 -> #REF! | BW15: 6500 | BX15: 621 | BY15: =#REF! -> #REF! | BZ15: =#REF! -> #REF! | CA15: =#REF! -> #REF! | CB15: =#REF! -> #REF! | CC15: =#REF! -> #REF! | CD15: =#REF! -> #REF! | CE15: =#REF! -> #REF! | CF15: =#REF! -> #REF! | ... DJ15: =#REF! -> #REF! | DK15: =BW15+BY15+CA15+CC15+CE15+CG15+CI15+CK15+CM15+CO15+CQ15+CS15+CU15+CW15+CY15+DA15+DC15+DE15+DG15+DI15 -> #REF! | DL15: =CX15+CV15+CT15+CR15+CP15+CN15+CL15+CJ15+CH15+CF15+CD15+CB15+BZ15+BX15+CZ15+DB15+DD15+DF15+DH15+DJ15 -> #REF! | DM15: =#REF! -> #REF! | DN15: =#REF! -> #REF! | DO15: =#REF! -> #REF! | DP15: =#REF! -> #REF! | DQ15: =#REF! -> #REF! | DR15: =#REF! -> #REF! | DS15: =#REF! -> #REF! | DT15: =#REF! -> #REF! | DU15: 217 | DV15: 89.3 | DW15: =DM15+DO15+DQ15+DS15+DU15 -> #REF! | DX15: =DN15+DP15+DR15+DT15+DV15 -> #REF! | DY15: =#REF! -> #REF! | DZ15: =#REF! -> #REF! | EA15: =#REF! -> #REF! | EB15: =#REF! -> #REF! | EC15: =#REF! -> #REF! | ED15: =#REF! -> #REF! | EE15: =#REF! -> #REF! | EF15: =#REF! -> #REF! | ... EL15: =#REF! -> #REF! | EM15: =DY15+EA15+EC15+EE15+EG15+EI15+EK15 -> #REF! | EN15: =DZ15+EB15+ED15+EF15+EH15+EJ15+EL15 -> #REF! | EO15: =#REF! -> #REF! | EP15: =#REF! -> #REF! | EQ15: =#REF! -> #REF! | ER15: =#REF! -> #REF! | ES15: =#REF! -> #REF! | ET15: =#REF! -> #REF! | EU15: =#REF! -> #REF! | EV15: =#REF! -> #REF! | ... FF15: =#REF! -> #REF! | FG15: =EO15+EQ15+ES15+EU15+EW15+EY15+FA15+FC15+FE15 -> #REF! | FH15: =FD15+FB15+EZ15+EX15+EV15+ET15+ER15+EP15+FF15 -> #REF! | FI15: =#REF! -> #REF! | FJ15: =#REF! -> #REF! | FK15: =#REF! -> #REF! | FL15: =#REF! -> #REF! | FM15: =#REF! -> #REF! | FN15: =#REF! -> #REF! | FO15: =#REF! -> #REF! | FP15: =#REF! -> #REF! | FQ15: =FI15+FK15+FM15+FO15 -> #REF! | FR15: =FJ15+FL15+FN15+FP15 -> #REF! | FS15: 47 | FT15: 19 | FV15: 2149.65 | FW15: =#REF! -> #REF! | FX15: =#REF! -> #REF!
A16: 9 | B16: Cuenca | C16: =#REF! -> #REF! | D16: 296 | E16: =C16+D16 -> #REF! | F16: =N16+V16+BV16+DL16+DX16+EN16+FH16+FR16+FT16+FV16+FX16 -> #REF! | G16: =#REF! -> #REF! | H16: =#REF! -> #REF! | I16: =#REF! -> #REF! | J16: =#REF! -> #REF! | K16: =#REF! -> #REF! | L16: =#REF! -> #REF! | M16: =G16+I16+K16 -> #REF! | N16: =H16+J16+L16 -> #REF! | O16: =#REF! -> #REF! | P16: =#REF! -> #REF! | Q16: =#REF! -> #REF! | R16: =#REF! -> #REF! | S16: =#REF! -> #REF! | T16: =#REF! -> #REF! | U16: =O16+Q16+S16 -> #REF! | V16: =P16+R16+T16 -> #REF! | W16: =#REF! -> #REF! | X16: =#REF! -> #REF! | Y16: =#REF! -> #REF! | Z16: =#REF! -> #REF! | AA16: =#REF! -> #REF! | AB16: =#REF! -> #REF! | AC16: =#REF! -> #REF! | AD16: =#REF! -> #REF! | AE16: 30 | AF16: =#REF! -> #REF! | AG16: =#REF! -> #REF! | AH16: =#REF! -> #REF! | AI16: =#REF! -> #REF! | AJ16: =#REF! -> #REF! | AK16: =#REF! -> #REF! | AL16: =#REF! -> #REF! | AM16: =#REF! -> #REF! | ... AR16: =#REF! -> #REF! | AS16: =W16+Y16+AA16+AC16+AE16+AG16+AI16+AK16+AM16+AO16+AQ16 -> #REF! | AT16: =X16+Z16+AB16+AD16+AF16+AH16+AJ16+AL16+AN16+AP16+AR16 -> #REF! | AU16: =#REF! -> #REF! | AV16: =#REF! -> #REF! | AW16: =#REF! -> #REF! | AX16: =#REF! -> #REF! | AY16: =#REF! -> #REF! | AZ16: =#REF! -> #REF! | BA16: =#REF! -> #REF! | BB16: =#REF! -> #REF! | ... BH16: =#REF! -> #REF! | BI16: =AU16+AW16+AY16+BA16+BC16+BE16+BG16 -> #REF! | BJ16: =AV16+AX16+AZ16+BB16+BD16+BH16+BF16 -> #REF! | BK16: =#REF! -> #REF! | BL16: =#REF! -> #REF! | BM16: =#REF! -> #REF! | BN16: =#REF! -> #REF! | BO16: =#REF! -> #REF! | BP16: =#REF! -> #REF! | BQ16: =BK16+BM16+BO16 -> #REF! | BR16: =BL16+BN16+BP16 -> #REF! | BS16: =#REF! -> #REF! | BT16: =#REF! -> #REF! | BU16: =AS16+BI16+BQ16+BS16 -> #REF! | BV16: =AT16+BJ16+BR16+BT16 -> #REF! | BW16: =#REF! -> #REF! | BX16: =#REF! -> #REF! | BY16: =#REF! -> #REF! | BZ16: =#REF! -> #REF! | CA16: =#REF! -> #REF! | CB16: =#REF! -> #REF! | CC16: =#REF! -> #REF! | CD16: =#REF! -> #REF! | ... DJ16: =#REF! -> #REF! | DK16: =BW16+BY16+CA16+CC16+CE16+CG16+CI16+CK16+CM16+CO16+CQ16+CS16+CU16+CW16+CY16+DA16+DC16+DE16+DG16+DI16 -> #REF! | DL16: =CX16+CV16+CT16+CR16+CP16+CN16+CL16+CJ16+CH16+CF16+CD16+CB16+BZ16+BX16+CZ16+DB16+DD16+DF16+DH16+DJ16 -> #REF! | DM16: =#REF! -> #REF! | DN16: =#REF! -> #REF! | DO16: =#REF! -> #REF! | DP16: =#REF! -> #REF! | DQ16: =#REF! -> #REF! | DR16: =#REF! -> #REF! | DS16: =#REF! -> #REF! | DT16: =#REF! -> #REF! | ... DV16: =#REF! -> #REF! | DW16: =DM16+DO16+DQ16+DS16+DU16 -> #REF! | DX16: =DN16+DP16+DR16+DT16+DV16 -> #REF! | DY16: =#REF! -> #REF! | DZ16: =#REF! -> #REF! | EA16: =#REF! -> #REF! | EB16: =#REF! -> #REF! | EC16: =#REF! -> #REF! | ED16: =#REF! -> #REF! | EE16: =#REF! -> #REF! | EF16: =#REF! -> #REF! | ... EL16: =#REF! -> #REF! | EM16: =DY16+EA16+EC16+EE16+EG16+EI16+EK16 -> #REF! | EN16: =DZ16+EB16+ED16+EF16+EH16+EJ16+EL16 -> #REF! | EO16: =#REF! -> #REF! | EP16: =#REF! -> #REF! | EQ16: =#REF! -> #REF! | ER16: =#REF! -> #REF! | ES16: =#REF! -> #REF! | ET16: =#REF! -> #REF! | EU16: =#REF! -> #REF! | EV16: =#REF! -> #REF! | ... FF16: =#REF! -> #REF! | FG16: =EO16+EQ16+ES16+EU16+EW16+EY16+FA16+FC16+FE16 -> #REF! | FH16: =FD16+FB16+EZ16+EX16+EV16+ET16+ER16+EP16+FF16 -> #REF! | FI16: =#REF! -> #REF! | FJ16: =#REF! -> #REF! | FK16: =#REF! -> #REF! | FL16: =#REF! -> #REF! | FM16: =#REF! -> #REF! | FN16: =#REF! -> #REF! | FO16: =#REF! -> #REF! | FP16: =#REF! -> #REF! | FQ16: =FI16+FK16+FM16+FO16 -> #REF! | FR16: =FJ16+FL16+FN16+FP16 -> #REF! | FS16: 411 | FT16: 674.61 | FV16: 117 | FZ16: Note: | GA16: Other Fruit Trees - not in the matrix, but data are included in the Total of "Fruit Trees"
A17: 10 | B17: Ibaan | C17: =#REF! -> #REF! | D17: =#REF! -> #REF! | E17: =C17+D17 -> #REF! | F17: =N17+V17+BV17+DL17+DX17+EN17+FH17+FR17+FT17+FV17+FX17 -> #REF! | G17: =#REF! -> #REF! | H17: =#REF! -> #REF! | I17: =#REF! -> #REF! | J17: =#REF! -> #REF! | K17: =#REF! -> #REF! | L17: =#REF! -> #REF! | M17: =G17+I17+K17 -> #REF! | N17: =H17+J17+L17 -> #REF! | O17: =#REF! -> #REF! | P17: =#REF! -> #REF! | Q17: =#REF! -> #REF! | R17: =#REF! -> #REF! | S17: =#REF! -> #REF! | T17: =#REF! -> #REF! | U17: =O17+Q17+S17 -> #REF! | V17: =P17+R17+T17 -> #REF! | W17: =#REF! -> #REF! | X17: =#REF! -> #REF! | Y17: =#REF! -> #REF! | Z17: =#REF! -> #REF! | AA17: =#REF! -> #REF! | AB17: =#REF! -> #REF! | AC17: =#REF! -> #REF! | AD17: =#REF! -> #REF! | ... AR17: =#REF! -> #REF! | AS17: =W17+Y17+AA17+AC17+AE17+AG17+AI17+AK17+AM17+AO17+AQ17 -> #REF! | AT17: =X17+Z17+AB17+AD17+AF17+AH17+AJ17+AL17+AN17+AP17+AR17 -> #REF! | AU17: =#REF! -> #REF! | AV17: =#REF! -> #REF! | AW17: =#REF! -> #REF! | AX17: =#REF! -> #REF! | AY17: =#REF! -> #REF! | AZ17: =#REF! -> #REF! | BA17: =#REF! -> #REF! | BB17: =#REF! -> #REF! | ... BH17: =#REF! -> #REF! | BI17: =AU17+AW17+AY17+BA17+BC17+BE17+BG17 -> #REF! | BJ17: =AV17+AX17+AZ17+BB17+BD17+BH17+BF17 -> #REF! | BK17: =#REF! -> #REF! | BL17: =#REF! -> #REF! | BM17: =#REF! -> #REF! | BN17: =#REF! -> #REF! | BO17: =#REF! -> #REF! | BP17: =#REF! -> #REF! | BQ17: =BK17+BM17+BO17 -> #REF! | BR17: =BL17+BN17+BP17 -> #REF! | BS17: =#REF! -> #REF! | BT17: =#REF! -> #REF! | BU17: =AS17+BI17+BQ17+BS17 -> #REF! | BV17: =AT17+BJ17+BR17+BT17 -> #REF! | BW17: =#REF! -> #REF! | BX17: =#REF! -> #REF! | BY17: =#REF! -> #REF! | BZ17: =#REF! -> #REF! | CA17: =#REF! -> #REF! | CB17: =#REF! -> #REF! | CC17: =#REF! -> #REF! | CD17: =#REF! -> #REF! | ... DJ17: =#REF! -> #REF! | DK17: =BW17+BY17+CA17+CC17+CE17+CG17+CI17+CK17+CM17+CO17+CQ17+CS17+CU17+CW17+CY17+DA17+DC17+DE17+DG17+DI17 -> #REF! | DL17: =CX17+CV17+CT17+CR17+CP17+CN17+CL17+CJ17+CH17+CF17+CD17+CB17+BZ17+BX17+CZ17+DB17+DD17+DF17+DH17+DJ17 -> #REF! | DM17: =#REF! -> #REF! | DN17: =#REF! -> #REF! | DO17: =#REF! -> #REF! | DP17: =#REF! -> #REF! | DQ17: =#REF! -> #REF! | DR17: =#REF! -> #REF! | DS17: =#REF! -> #REF! | DT17: =#REF! -> #REF! | ... DV17: =#REF! -> #REF! | DW17: =DM17+DO17+DQ17+DS17+DU17 -> #REF! | DX17: =DN17+DP17+DR17+DT17+DV17 -> #REF! | DY17: =#REF! -> #REF! | DZ17: =#REF! -> #REF! | EA17: =#REF! -> #REF! | EB17: =#REF! -> #REF! | EC17: =#REF! -> #REF! | ED17: =#REF! -> #REF! | EE17: =#REF! -> #REF! | EF17: =#REF! -> #REF! | ... EL17: =#REF! -> #REF! | EM17: =DY17+EA17+EC17+EE17+EG17+EI17+EK17 -> #REF! | EN17: =DZ17+EB17+ED17+EF17+EH17+EJ17+EL17 -> #REF! | EO17: =#REF! -> #REF! | EP17: =#REF! -> #REF! | EQ17: =#REF! -> #REF! | ER17: =#REF! -> #REF! | ES17: =#REF! -> #REF! | ET17: =#REF! -> #REF! | EU17: =#REF! -> #REF! | EV17: =#REF! -> #REF! | ... FF17: =#REF! -> #REF! | FG17: =EO17+EQ17+ES17+EU17+EW17+EY17+FA17+FC17+FE17 -> #REF! | FH17: =FD17+FB17+EZ17+EX17+EV17+ET17+ER17+EP17+FF17 -> #REF! | FI17: =#REF! -> #REF! | FJ17: =#REF! -> #REF! | FK17: =#REF! -> #REF! | FL17: =#REF! -> #REF! | FM17: =#REF! -> #REF! | FN17: =#REF! -> #REF! | FO17: =#REF! -> #REF! | FP17: =#REF! -> #REF! | FQ17: =FI17+FK17+FM17+FO17 -> #REF! | FR17: =FJ17+FL17+FN17+FP17 -> #REF! | FS17: 96 | FT17: 74 | FV17: 1376 | FW17: 51 | FX17: 2.5 | GA17: Batangas City- Other Fruit Trees , NF - 1,040, A - 2,400.00
A18: 11 | B18: Laurel | C18: =#REF! -> #REF! | D18: =#REF! -> #REF! | E18: =C18+D18 -> #REF! | F18: =N18+V18+BV18+DL18+DX18+EN18+FH18+FR18+FT18+FV18+FX18 -> #REF! | G18: 306 | H18: 230 | I18: =#REF! -> #REF! | J18: =#REF! -> #REF! | K18: 83 | L18: 41.5 | M18: =G18+I18+K18 -> #REF! | N18: =H18+J18+L18 -> #REF! | O18: =#REF! -> #REF! | P18: =#REF! -> #REF! | Q18: =#REF! -> #REF! | R18: =#REF! -> #REF! | S18: =#REF! -> #REF! | T18: =#REF! -> #REF! | U18: =O18+Q18+S18 -> #REF! | V18: =P18+R18+T18 -> #REF! | W18: =#REF! -> #REF! | X18: =#REF! -> #REF! | Y18: =#REF! -> #REF! | Z18: =#REF! -> #REF! | AA18: =#REF! -> #REF! | AB18: =#REF! -> #REF! | AC18: =#REF! -> #REF! | AD18: =#REF! -> #REF! | ... AR18: =#REF! -> #REF! | AS18: =W18+Y18+AA18+AC18+AE18+AG18+AI18+AK18+AM18+AO18+AQ18 -> #REF! | AT18: =X18+Z18+AB18+AD18+AF18+AH18+AJ18+AL18+AN18+AP18+AR18 -> #REF! | AU18: =#REF! -> #REF! | AV18: =#REF! -> #REF! | AW18: =#REF! -> #REF! | AX18: =#REF! -> #REF! | AY18: =#REF! -> #REF! | AZ18: =#REF! -> #REF! | BA18: =#REF! -> #REF! | BB18: =#REF! -> #REF! | ... BH18: =#REF! -> #REF! | BI18: =AU18+AW18+AY18+BA18+BC18+BE18+BG18 -> #REF! | BJ18: =AV18+AX18+AZ18+BB18+BD18+BH18+BF18 -> #REF! | BK18: =#REF! -> #REF! | BL18: =#REF! -> #REF! | BM18: =#REF! -> #REF! | BN18: =#REF! -> #REF! | BO18: =#REF! -> #REF! | BP18: =#REF! -> #REF! | BQ18: =BK18+BM18+BO18 -> #REF! | BR18: =BL18+BN18+BP18 -> #REF! | BS18: =#REF! -> #REF! | BT18: =#REF! -> #REF! | BU18: =AS18+BI18+BQ18+BS18 -> #REF! | BV18: =AT18+BJ18+BR18+BT18 -> #REF! | BW18: =#REF! -> #REF! | BX18: =#REF! -> #REF! | BY18: =#REF! -> #REF! | BZ18: =#REF! -> #REF! | CA18: =#REF! -> #REF! | CB18: =#REF! -> #REF! | CC18: =#REF! -> #REF! | CD18: =#REF! -> #REF! | ... DJ18: =#REF! -> #REF! | DK18: =BW18+BY18+CA18+CC18+CE18+CG18+CI18+CK18+CM18+CO18+CQ18+CS18+CU18+CW18+CY18+DA18+DC18+DE18+DG18+DI18 -> #REF! | DL18: =CX18+CV18+CT18+CR18+CP18+CN18+CL18+CJ18+CH18+CF18+CD18+CB18+BZ18+BX18+CZ18+DB18+DD18+DF18+DH18+DJ18 -> #REF! | DM18: =#REF! -> #REF! | DN18: =#REF! -> #REF! | DO18: =#REF! -> #REF! | DP18: =#REF! -> #REF! | DQ18: =#REF! -> #REF! | DR18: =#REF! -> #REF! | DS18: =#REF! -> #REF! | DT18: =#REF! -> #REF! | ... DV18: =#REF! -> #REF! | DW18: =DM18+DO18+DQ18+DS18+DU18 -> #REF! | DX18: =DN18+DP18+DR18+DT18+DV18 -> #REF! | DY18: =#REF! -> #REF! | DZ18: =#REF! -> #REF! | EA18: =#REF! -> #REF! | EB18: =#REF! -> #REF! | EC18: =#REF! -> #REF! | ED18: =#REF! -> #REF! | EE18: =#REF! -> #REF! | EF18: =#REF! -> #REF! | ... EL18: =#REF! -> #REF! | EM18: =DY18+EA18+EC18+EE18+EG18+EI18+EK18 -> #REF! | EN18: =DZ18+EB18+ED18+EF18+EH18+EJ18+EL18 -> #REF! | EO18: =#REF! -> #REF! | EP18: =#REF! -> #REF! | EQ18: =#REF! -> #REF! | ER18: =#REF! -> #REF! | ES18: =#REF! -> #REF! | ET18: =#REF! -> #REF! | EU18: =#REF! -> #REF! | EV18: =#REF! -> #REF! | ... FF18: =#REF! -> #REF! | FG18: =EO18+EQ18+ES18+EU18+EW18+EY18+FA18+FC18+FE18 -> #REF! | FH18: =FD18+FB18+EZ18+EX18+EV18+ET18+ER18+EP18+FF18 -> #REF! | FI18: =#REF! -> #REF! | FJ18: =#REF! -> #REF! | FK18: =#REF! -> #REF! | FL18: =#REF! -> #REF! | FM18: =#REF! -> #REF! | FN18: =#REF! -> #REF! | FO18: =#REF! -> #REF! | FP18: =#REF! -> #REF! | FQ18: =FI18+FK18+FM18+FO18 -> #REF! | FR18: =FJ18+FL18+FN18+FP18 -> #REF! | FS18: 588 | FT18: 894 | FU18: =#REF! -> #REF! | FV18: =#REF! -> #REF! | GA18: Lobo - Other crops , NF - 953, A - 7.98
A19: 12 | B19: Lemery | C19: =#REF! -> #REF! | D19: =#REF! -> #REF! | E19: =C19+D19 -> #REF! | F19: =N19+V19+BV19+DL19+DX19+EN19+FH19+FR19+FT19+FV19+FX19 -> #REF! | G19: =#REF! -> #REF! | H19: =#REF! -> #REF! | I19: =#REF! -> #REF! | J19: =#REF! -> #REF! | K19: =#REF! -> #REF! | L19: =#REF! -> #REF! | M19: =G19+I19+K19 -> #REF! | N19: =H19+J19+L19 -> #REF! | O19: 277 | P19: 150 | Q19: 1458 | R19: 1359.22 | S19: =#REF! -> #REF! | T19: =#REF! -> #REF! | U19: =O19+Q19+S19 -> #REF! | V19: =P19+R19+T19 -> #REF! | W19: =#REF! -> #REF! | X19: =#REF! -> #REF! | Y19: =#REF! -> #REF! | Z19: =#REF! -> #REF! | AA19: =#REF! -> #REF! | AB19: =#REF! -> #REF! | AC19: =#REF! -> #REF! | AD19: =#REF! -> #REF! | ... AR19: =#REF! -> #REF! | AS19: =W19+Y19+AA19+AC19+AE19+AG19+AI19+AK19+AM19+AO19+AQ19 -> #REF! | AT19: =X19+Z19+AB19+AD19+AF19+AH19+AJ19+AL19+AN19+AP19+AR19 -> #REF! | AU19: =#REF! -> #REF! | AV19: =#REF! -> #REF! | AW19: =#REF! -> #REF! | AX19: =#REF! -> #REF! | AY19: =#REF! -> #REF! | AZ19: =#REF! -> #REF! | BA19: =#REF! -> #REF! | BB19: =#REF! -> #REF! | ... BH19: =#REF! -> #REF! | BI19: =AU19+AW19+AY19+BA19+BC19+BE19+BG19 -> #REF! | BJ19: =AV19+AX19+AZ19+BB19+BD19+BH19+BF19 -> #REF! | BK19: =#REF! -> #REF! | BL19: =#REF! -> #REF! | BM19: =#REF! -> #REF! | BN19: =#REF! -> #REF! | BO19: =#REF! -> #REF! | BP19: =#REF! -> #REF! | BQ19: =BK19+BM19+BO19 -> #REF! | BR19: =BL19+BN19+BP19 -> #REF! | BS19: =#REF! -> #REF! | BT19: =#REF! -> #REF! | BU19: =AS19+BI19+BQ19+BS19 -> #REF! | BV19: =AT19+BJ19+BR19+BT19 -> #REF! | BW19: =#REF! -> #REF! | BX19: =#REF! -> #REF! | BY19: =#REF! -> #REF! | BZ19: =#REF! -> #REF! | CA19: =#REF! -> #REF! | CB19: =#REF! -> #REF! | CC19: =#REF! -> #REF! | CD19: =#REF! -> #REF! | ... DJ19: =#REF! -> #REF! | DK19: =BW19+BY19+CA19+CC19+CE19+CG19+CI19+CK19+CM19+CO19+CQ19+CS19+CU19+CW19+CY19+DA19+DC19+DE19+DG19+DI19 -> #REF! | DL19: =CX19+CV19+CT19+CR19+CP19+CN19+CL19+CJ19+CH19+CF19+CD19+CB19+BZ19+BX19+CZ19+DB19+DD19+DF19+DH19+DJ19 -> #REF! | DM19: =#REF! -> #REF! | DN19: =#REF! -> #REF! | DO19: =#REF! -> #REF! | DP19: =#REF! -> #REF! | DQ19: =#REF! -> #REF! | DR19: =#REF! -> #REF! | DS19: =#REF! -> #REF! | DT19: =#REF! -> #REF! | ... DV19: =#REF! -> #REF! | DW19: =DM19+DO19+DQ19+DS19+DU19 -> #REF! | DX19: =DN19+DP19+DR19+DT19+DV19 -> #REF! | DY19: =#REF! -> #REF! | DZ19: =#REF! -> #REF! | EA19: =#REF! -> #REF! | EB19: =#REF! -> #REF! | EC19: =#REF! -> #REF! | ED19: =#REF! -> #REF! | EE19: =#REF! -> #REF! | EF19: =#REF! -> #REF! | EG19: 194 | EH19: 72.73 | EI19: 133 | EJ19: 33.52 | EK19: =#REF! -> #REF! | EL19: =#REF! -> #REF! | EM19: =DY19+EA19+EC19+EE19+EG19+EI19+EK19 -> #REF! | EN19: =DZ19+EB19+ED19+EF19+EH19+EJ19+EL19 -> #REF! | EO19: =#REF! -> #REF! | EP19: =#REF! -> #REF! | EQ19: =#REF! -> #REF! | ER19: =#REF! -> #REF! | ES19: =#REF! -> #REF! | ET19: =#REF! -> #REF! | EU19: =#REF! -> #REF! | EV19: =#REF! -> #REF! | ... FF19: =#REF! -> #REF! | FG19: =EO19+EQ19+ES19+EU19+EW19+EY19+FA19+FC19+FE19 -> #REF! | FH19: =FD19+FB19+EZ19+EX19+EV19+ET19+ER19+EP19+FF19 -> #REF! | FI19: =#REF! -> #REF! | FJ19: =#REF! -> #REF! | FK19: =#REF! -> #REF! | FL19: =#REF! -> #REF! | FM19: =#REF! -> #REF! | FN19: =#REF! -> #REF! | FO19: =#REF! -> #REF! | FP19: =#REF! -> #REF! | FQ19: =FI19+FK19+FM19+FO19 -> #REF! | FR19: =FJ19+FL19+FN19+FP19 -> #REF! | FS19: 2417 | FT19: 2897.6 | FU19: =#REF! -> #REF! | FV19: 147 | FW19: =#REF! -> #REF! | FX19: =#REF! -> #REF! | GA19: Mabini - Other Fruit Trees , NF - 459, A - 195.00
A20: 13 | B20: Lian | C20: =#REF! -> #REF! | D20: =#REF! -> #REF! | E20: =C20+D20 -> #REF! | F20: =N20+V20+BV20+DL20+DX20+EN20+FH20+FR20+FT20+FV20+FX20 -> #REF! | G20: 576 | H20: 563 | I20: 218 | J20: 201 | K20: 148 | L20: 123.25 | M20: =G20+I20+K20 -> 942 | N20: =H20+J20+L20 -> 887.25 | O20: =#REF! -> #REF! | P20: =#REF! -> #REF! | Q20: =#REF! -> #REF! | R20: =#REF! -> #REF! | S20: =#REF! -> #REF! | T20: =#REF! -> #REF! | U20: =O20+Q20+S20 -> #REF! | V20: =P20+R20+T20 -> #REF! | W20: =#REF! -> #REF! | X20: =#REF! -> #REF! | Y20: =#REF! -> #REF! | Z20: =#REF! -> #REF! | AA20: =#REF! -> #REF! | AB20: =#REF! -> #REF! | AC20: =#REF! -> #REF! | AD20: =#REF! -> #REF! | ... AR20: =#REF! -> #REF! | AS20: =W20+Y20+AA20+AC20+AE20+AG20+AI20+AK20+AM20+AO20+AQ20 -> #REF! | AT20: =X20+Z20+AB20+AD20+AF20+AH20+AJ20+AL20+AN20+AP20+AR20 -> #REF! | AU20: =#REF! -> #REF! | AV20: =#REF! -> #REF! | AW20: =#REF! -> #REF! | AX20: =#REF! -> #REF! | AY20: =#REF! -> #REF! | AZ20: =#REF! -> #REF! | BA20: =#REF! -> #REF! | BB20: =#REF! -> #REF! | ... BH20: =#REF! -> #REF! | BI20: =AU20+AW20+AY20+BA20+BC20+BE20+BG20 -> #REF! | BJ20: =AV20+AX20+AZ20+BB20+BD20+BH20+BF20 -> #REF! | BK20: =#REF! -> #REF! | BL20: =#REF! -> #REF! | BM20: =#REF! -> #REF! | BN20: =#REF! -> #REF! | BO20: =#REF! -> #REF! | BP20: =#REF! -> #REF! | BQ20: =BK20+BM20+BO20 -> #REF! | BR20: =BL20+BN20+BP20 -> #REF! | BS20: =#REF! -> #REF! | BT20: =#REF! -> #REF! | BU20: =AS20+BI20+BQ20+BS20 -> #REF! | BV20: =AT20+BJ20+BR20+BT20 -> #REF! | BW20: =#REF! -> #REF! | BX20: =#REF! -> #REF! | BY20: =#REF! -> #REF! | BZ20: =#REF! -> #REF! | CA20: =#REF! -> #REF! | CB20: =#REF! -> #REF! | CC20: =#REF! -> #REF! | CD20: =#REF! -> #REF! | ... DJ20: =#REF! -> #REF! | DK20: =BW20+BY20+CA20+CC20+CE20+CG20+CI20+CK20+CM20+CO20+CQ20+CS20+CU20+CW20+CY20+DA20+DC20+DE20+DG20+DI20 -> #REF! | DL20: =CX20+CV20+CT20+CR20+CP20+CN20+CL20+CJ20+CH20+CF20+CD20+CB20+BZ20+BX20+CZ20+DB20+DD20+DF20+DH20+DJ20 -> #REF! | DM20: =#REF! -> #REF! | DN20: =#REF! -> #REF! | DO20: =#REF! -> #REF! | DP20: =#REF! -> #REF! | DQ20: =#REF! -> #REF! | DR20: =#REF! -> #REF! | DS20: =#REF! -> #REF! | DT20: =#REF! -> #REF! | ... DV20: =#REF! -> #REF! | DW20: =DM20+DO20+DQ20+DS20+DU20 -> #REF! | DX20: =DN20+DP20+DR20+DT20+DV20 -> #REF! | DY20: =#REF! -> #REF! | DZ20: =#REF! -> #REF! | EA20: =#REF! -> #REF! | EB20: =#REF! -> #REF! | EC20: =#REF! -> #REF! | ED20: =#REF! -> #REF! | EE20: =#REF! -> #REF! | EF20: =#REF! -> #REF! | ... EL20: =#REF! -> #REF! | EM20: =DY20+EA20+EC20+EE20+EG20+EI20+EK20 -> #REF! | EN20: =DZ20+EB20+ED20+EF20+EH20+EJ20+EL20 -> #REF! | EO20: =#REF! -> #REF! | EP20: =#REF! -> #REF! | EQ20: =#REF! -> #REF! | ER20: =#REF! -> #REF! | ES20: =#REF! -> #REF! | ET20: =#REF! -> #REF! | EU20: =#REF! -> #REF! | EV20: =#REF! -> #REF! | ... FF20: =#REF! -> #REF! | FG20: =EO20+EQ20+ES20+EU20+EW20+EY20+FA20+FC20+FE20 -> #REF! | FH20: =FD20+FB20+EZ20+EX20+EV20+ET20+ER20+EP20+FF20 -> #REF! | FI20: =#REF! -> #REF! | FJ20: =#REF! -> #REF! | FK20: =#REF! -> #REF! | FL20: =#REF! -> #REF! | FM20: =#REF! -> #REF! | FN20: =#REF! -> #REF! | FO20: =#REF! -> #REF! | FP20: =#REF! -> #REF! | FQ20: =FI20+FK20+FM20+FO20 -> #REF! | FR20: =FJ20+FL20+FN20+FP20 -> #REF! | FS20: 67 | FT20: 66 | FU20: =#REF! -> #REF! | FV20: 2110.06 | FW20: =#REF! -> #REF! | FX20: =#REF! -> #REF! | GA20: Mataas na Kahoy- Other Fruit Trees , NF - 22, A - 4.53
A21: 14 | B21: Lipa City | C21: =#REF! -> #REF! | E21: =C21+D21 -> #REF! | F21: =N21+V21+BV21+DL21+DX21+EN21+FH21+FR21+FT21+FV21+FX21 -> #REF! | G21: 48 | H21: 61.75 | I21: =#REF! -> #REF! | J21: =#REF! -> #REF! | K21: 27 | L21: 34 | M21: =G21+I21+K21 -> #REF! | N21: =H21+J21+L21 -> #REF! | O21: 15 | P21: 117.5 | Q21: 272 | R21: 279.98 | S21: =#REF! -> #REF! | T21: =#REF! -> #REF! | U21: =O21+Q21+S21 -> #REF! | V21: =P21+R21+T21 -> #REF! | W21: =#REF! -> #REF! | X21: =#REF! -> #REF! | Y21: =#REF! -> #REF! | Z21: =#REF! -> #REF! | AA21: =#REF! -> #REF! | AB21: =#REF! -> #REF! | AC21: =#REF! -> #REF! | AD21: =#REF! -> #REF! | ... AR21: =#REF! -> #REF! | AS21: =W21+Y21+AA21+AC21+AE21+AG21+AI21+AK21+AM21+AO21+AQ21 -> #REF! | AT21: =X21+Z21+AB21+AD21+AF21+AH21+AJ21+AL21+AN21+AP21+AR21 -> #REF! | AU21: =#REF! -> #REF! | AV21: =#REF! -> #REF! | AW21: =#REF! -> #REF! | AX21: =#REF! -> #REF! | AY21: =#REF! -> #REF! | AZ21: =#REF! -> #REF! | BA21: =#REF! -> #REF! | BB21: =#REF! -> #REF! | ... BH21: =#REF! -> #REF! | BI21: =AU21+AW21+AY21+BA21+BC21+BE21+BG21 -> #REF! | BJ21: =AV21+AX21+AZ21+BB21+BD21+BH21+BF21 -> #REF! | BK21: =#REF! -> #REF! | BL21: =#REF! -> #REF! | BM21: =#REF! -> #REF! | BN21: =#REF! -> #REF! | BO21: =#REF! -> #REF! | BP21: =#REF! -> #REF! | BQ21: =BK21+BM21+BO21 -> #REF! | BR21: =BL21+BN21+BP21 -> #REF! | BS21: =#REF! -> #REF! | BT21: =#REF! -> #REF! | BU21: =AS21+BI21+BQ21+BS21 -> #REF! | BV21: =AT21+BJ21+BR21+BT21 -> #REF! | BW21: =#REF! -> #REF! | BX21: =#REF! -> #REF! | BY21: =#REF! -> #REF! | BZ21: =#REF! -> #REF! | CA21: =#REF! -> #REF! | CB21: =#REF! -> #REF! | CC21: =#REF! -> #REF! | CD21: =#REF! -> #REF! | ... DJ21: =#REF! -> #REF! | DK21: =BW21+BY21+CA21+CC21+CE21+CG21+CI21+CK21+CM21+CO21+CQ21+CS21+CU21+CW21+CY21+DA21+DC21+DE21+DG21+DI21 -> #REF! | DL21: =CX21+CV21+CT21+CR21+CP21+CN21+CL21+CJ21+CH21+CF21+CD21+CB21+BZ21+BX21+CZ21+DB21+DD21+DF21+DH21+DJ21 -> #REF! | DM21: =#REF! -> #REF! | DN21: =#REF! -> #REF! | DO21: =#REF! -> #REF! | DP21: =#REF! -> #REF! | DQ21: =#REF! -> #REF! | DR21: =#REF! -> #REF! | DS21: =#REF! -> #REF! | DT21: =#REF! -> #REF! | ... DV21: =#REF! -> #REF! | DW21: =DM21+DO21+DQ21+DS21+DU21 -> #REF! | DX21: =DN21+DP21+DR21+DT21+DV21 -> #REF! | DY21: =#REF! -> #REF! | DZ21: =#REF! -> #REF! | EA21: =#REF! -> #REF! | EB21: =#REF! -> #REF! | EC21: =#REF! -> #REF! | ED21: =#REF! -> #REF! | EE21: =#REF! -> #REF! | EF21: =#REF! -> #REF! | ... EL21: =#REF! -> #REF! | EM21: =DY21+EA21+EC21+EE21+EG21+EI21+EK21 -> #REF! | EN21: =DZ21+EB21+ED21+EF21+EH21+EJ21+EL21 -> #REF! | EO21: =#REF! -> #REF! | EP21: =#REF! -> #REF! | EQ21: =#REF! -> #REF! | ER21: =#REF! -> #REF! | ES21: =#REF! -> #REF! | ET21: =#REF! -> #REF! | EU21: =#REF! -> #REF! | EV21: =#REF! -> #REF! | ... FF21: =#REF! -> #REF! | FG21: =EO21+EQ21+ES21+EU21+EW21+EY21+FA21+FC21+FE21 -> #REF! | FH21: =FD21+FB21+EZ21+EX21+EV21+ET21+ER21+EP21+FF21 -> #REF! | FI21: =#REF! -> #REF! | FJ21: =#REF! -> #REF! | FK21: =#REF! -> #REF! | FL21: =#REF! -> #REF! | FM21: =#REF! -> #REF! | FN21: =#REF! -> #REF! | FO21: =#REF! -> #REF! | FP21: =#REF! -> #REF! | FQ21: =FI21+FK21+FM21+FO21 -> #REF! | FR21: =FJ21+FL21+FN21+FP21 -> #REF! | FS21: 1317 | FT21: 2036.21 | FU21: =#REF! -> #REF! | FV21: 568 | FW21: =#REF! -> #REF! | FX21: =#REF! -> #REF! | GA21: San Juan - Other Fruit Trees , NF - 308, A - 370.08
A22: 15 | B22: Lobo | E22: =M22+U22+BU22+DK22+DW22+EM22+FG22+FQ22+FS22+FU22+FW22 -> #REF! | F22: =N22+V22+BV22+DL22+DX22+EN22+FH22+FR22+FT22+FV22+FX22 -> 2501.382 | G22: 498 | H22: 232.54 | K22: 126 | L22: 36.63 | M22: =G22+I22+K22 -> 624 | N22: =H22+J22+L22 -> 269.17 | U22: 347 | V22: 14 | W22: 59 | X22: 0.1 | Y22: 424 | Z22: 0.56 | AA22: 179 | AB22: 0.27 | AC22: 209 | AD22: 0.14 | AE22: 431 | AF22: 0.44 | AG22: 54 | AH22: 0.2 | AI22: 44 | AJ22: 0.08 | AK22: 89 | AL22: 0.11 | AS22: =W22+Y22+AA22+AC22+AE22+AG22+AI22+AK22+AM22+AO22+AQ22 -> 1489 | AT22: =X22+Z22+AB22+AD22+AF22+AH22+AJ22+AL22+AN22+AP22+AR22 -> 1.9 | AU22: 13 | AV22: 0.06 | AW22: 20 | AX22: 0.34 | BE22: 1234 | BF22: 8.72 | BI22: =AU22+AW22+AY22+BA22+BC22+BE22+BG22 -> 1267 | BJ22: =AV22+AX22+AZ22+BB22+BD22+BH22+BF22 -> 9.12 | BK22: 12 | BL22: 0.002 | BQ22: =BK22+BM22+BO22 -> 12 | BR22: =BL22+BN22+BP22 -> 0.002 | BU22: =AS22+BI22+BQ22+BS22 -> 2768 | BV22: =AT22+BJ22+BR22+BT22 -> 11.022 | BW22: 3333 | BX22: 125.49 | CA22: 211 | CB22: 9.23 | CC22: 147 | CD22: 7.08 | CE22: 987 | CF22: 77.69 | CG22: 1825 | CH22: 27.72 | CI22: 831 | CJ22: 42.26 | CK22: 245 | CL22: 31.96 | CM22: 107 | CN22: 1.75 | CQ22: 1016 | CR22: 38.16 | CS22: 1070 | CT22: 44.52 | CY22: 152 | CZ22: 2.92 | DA22: 762 | DB22: 41.79 | DC22: 140 | DD22: 1.23 | DK22: =BW22+BY22+CA22+CC22+CE22+CG22+CI22+CK22+CM22+CO22+CQ22+CS22+CU22+CW22+CY22+DA22+DC22+DE22+DG22+DI22+477+10 -> 11313 | DL22: =CX22+CV22+CT22+CR22+CP22+CN22+CL22+CJ22+CH22+CF22+CD22+CB22+BZ22+BX22+CZ22+DB22+DD22+DF22+DH22+DJ22+3.15+0.63 -> 455.58 | DQ22: 851 | DR22: 10 | DU22: 566 | DV22: 2.06 | DW22: =DM22+DO22+DQ22+DS22+DU22 -> 1417 | DX22: =DN22+DP22+DR22+DT22+DV22 -> 12.06 | DY22: 184 | DZ22: 1.17 | EA22: 824 | EB22: 2.43 | EE22: 400 | EF22: 0.77 | EM22: =DY22+EA22+EC22+EE22+EG22+EI22+EK22+466 -> 1874 | EN22: =DZ22+EB22+ED22+EF22+EH22+EJ22+EL22+4.2 -> 8.57 | FG22: 745 | FH22: 3.23 | FI22: 442 | FJ22: 9.55 | FK22: 410 | FL22: 7.79 | FO22: 1123 | FP22: 97.93 | FQ22: =FI22+FK22+FM22+FO22 -> 1975 | FR22: =FJ22+FL22+FN22+FP22 -> 115.27 | FS22: 1174 | FT22: 1606 | FU22: =#REF! -> #REF! | FW22: 324 | FX22: 6.48 | GA22: Sta. Teresita - Other Fruit Trees , NF - 40, A - 0.52
