Workbook
Name S: #REF!
Name S: #REF!
Name S: #REF!
Name S: #REF!
Name S: #REF!
Name S: #REF!
Name S: #REF!
Name S: #REF!
Name S: #REF!
Name S: #REF!
Name S: #REF!

Sheet Piamonte HVCDP
A1: District | C1: Barangay | D1: Farmers Served (No.) | E1: Existing Area (ha) | N1: Farmers Served (No.) | O1: Expansion Area (ha) | X1: REMARKS
E2: Area Planted (ha) | H2: Area Harvested (ha) | K2: Production (MT) | O2: Area Planted (ha) | R2: Area Harvested (ha) | U2: Production (MT)
E4: Previous | F4: This Mo. | G4: To Date | H4: Previous | I4: This Mo. | J4: To Date | K4: Previous | L4: This Mo. | M4: To Date | O4: Previous | P4: This Mo. | Q4: To Date | R4: Previous | S4: This Mo. | T4: To Date | U4: Previous | V4: This Mo. | W4: To Date
A5: III | B5: FRUIT VEGETABLES
B6: Eggplant | C6: Altura Matanda
C7: Altura South
C8: Banadero | D8: 3 | E8: 1.4 | G8: 1.4 | H8: 1.4 | J8: 1.4 | K8: 15.4 | M8: 15.4
C9: Bilog Bilog | D9: 3 | E9: 1.3 | G9: 1.3 | I9: 0.4 | J9: 0.4 | L9: 0.44 | M9: 0.44
C10: Luyos
C11: Malaking Pulo
C12: Montana | D12: 7 | E12: 3.2 | F12: 1.2 | G12: 4.4 | H12: 2.7 | J12: 2.7 | K12: 28.9 | M12: 28.9
C13: Sala
C14: Santol | D14: 4 | E14: 2.55 | G14: 2.55 | H14: 3.05 | J14: 3.05 | K14: 27.6 | M14: 27.6
C15: Sulpoc | D15: 1 | F15: 0.9 | G15: 0.9
C16: TOTAL | D16: =SUM(D6:D15) -> 18 | E16: =SUM(E6:E15) -> 8.45 | F16: =SUM(F6:F15) -> 2.1 | G16: =SUM(G6:G15) -> 10.55 | H16: =SUM(H6:H15) -> 7.15 | I16: =SUM(I6:I15) -> 0.4 | J16: =SUM(J6:J15) -> 7.55 | K16: =SUM(K6:K15) -> 71.9 | ... W16: =SUM(W6:W15) -> 0
B17: Sitao | C17: Altura Matanda
C18: Altura South
C19: Banadero | D19: 1 | E19: 0.35 | G19: 0.35
C20: Bilog Bilog | D20: 36 | E20: 16.35 | F20: 0.25 | G20: 16.6 | H20: 8.15 | J20: 8.15 | K20: 33.7 | M20: 33.7
C21: Luyos
C22: Malaking Pulo
C23: Montana | D23: 7 | E23: 2.52 | G23: 2.52 | H23: 1.57 | J23: 1.57 | K23: 16.62 | M23: 16.62
C24: Sala | D24: 5 | E24: 0.85 | G24: 0.85 | H24: 0.35 | J24: 0.35 | K24: 4.2 | M24: 4.2
C25: Santol | D25: 3 | E25: 0.8 | G25: 0.8 | H25: 1.35 | J25: 1.35 | K25: 11.2 | M25: 11.2
C26: Sulpoc | D26: 8 | E26: 2.95 | F26: 1 | G26: 3.95 | H26: 2.55 | J26: 2.55 | K26: 25.6 | M26: 25.6
C27: TOTAL | D27: =SUM(D17:D26) -> 60 | E27: =SUM(E17:E26) -> 23.82 | F27: =SUM(F17:F26) -> 1.25 | G27: =SUM(G17:G26) -> 25.07 | H27: =SUM(H17:H26) -> 13.97 | I27: =SUM(I17:I26) -> 0 | J27: =SUM(J17:J26) -> 13.97 | K27: =SUM(K17:K26) -> 91.32 | ... W27: =SUM(W17:W26) -> 0
B28: Squash | C28: Altura Matanda | D28: 3 | E28: 1.4 | G28: 1.4 | H28: 1.4 | J28: 1.4 | K28: 14 | M28: 14
C29: Altura South
C30: Banadero
C31: Bilog Bilog | D31: 17 | E31: 7.25 | F31: 0.5 | G31: 7.75 | H31: 2.25 | J31: 2.25 | K31: 15.3 | M31: 15.3
C32: Luyos | D32: 3 | E32: 0.4 | F32: 0.7 | G32: 1.1 | H32: 0.4 | J32: 0.4 | K32: 4 | M32: 4
C33: Malaking Pulo
C34: Montana | D34: 2 | E34: 1.25 | G34: 1.25 | H34: 0.25 | J34: 0.25 | K34: 2.5 | M34: 2.5
C35: Sala | D35: 2 | E35: 0.5 | G35: 0.5 | H35: 0.6 | J35: 0.6 | K35: 6 | M35: 6
C36: Santol
C37: Sulpoc | D37: 2 | E37: 0.8 | G37: 0.8 | H37: 0.8 | J37: 0.8 | K37: 8 | M37: 8
C38: TOTAL | D38: =SUM(D28:D37) -> 29 | E38: =SUM(E28:E37) -> 11.6 | F38: =SUM(F28:F37) -> 1.2 | G38: =SUM(G28:G37) -> 12.8 | H38: =SUM(H28:H37) -> 5.7 | I38: =SUM(I28:I37) -> 0 | J38: =SUM(J28:J37) -> 5.7 | K38: =SUM(K28:K37) -> 49.8 | ... W38: =SUM(W28:W37) -> 0
B39: Okra | C39: Altura Matanda
C40: Altura South
C41: Banadero
...

Sheet Requizo HVCDP
A1: District | B1: Commodity | C1: Barangay | D1: Farmers Served (No.) | E1: Existing Area (ha) | N1: Farmers Served (No.) | O1: Expansion Area (ha) | X1: REMARKS
E2: Area Planted (ha) | H2: Area Harvested (ha) | K2: Production (MT) | O2: Area Planted (ha) | R2: Area Harvested (ha) | U2: Production (MT)
E4: Previous | F4: This Mo. | G4: To Date | H4: Previous | I4: This Mo. | J4: To Date | K4: Previous | L4: This Mo. | O4: Previous | P4: This Mo. | Q4: To Date | R4: Previous | S4: This Mo. | T4: To Date | U4: Previous | V4: This Mo. | W4: To Date
B5: FRUIT VEGETABLES
B6: Eggplant | C6: Altura Bata | D6: 2 | E6: 0.3 | G6: 0.3 | H6: 0.3 | J6: 0.3 | K6: 3.3 | M6: 3.3
C7: Ambulong | D7: 1 | E7: 1 | G7: 1
C8: Gonzales | D8: 1 | E8: 0.33 | G8: 0.33 | H8: 0.33 | J8: 0.33 | K8: 3.43 | M8: 3.43
C9: Janopol Occ
C10: Janopol Or
C11: Pantay Matanda
C12: San Jose | D12: 13 | E12: 4.35 | G12: 4.35 | H12: 0.95 | J12: 0.95 | K12: 10.45 | M12: 10.45 | X12: 1.7 Damaged by Kristine
C13: Santor
C14: Talaga | D14: 1 | E14: 0.25 | G14: 0.25 | H14: 0.25 | J14: 0.25 | K14: 2.75 | M14: 2.75
C15: Trapiche | D15: 1 | E15: 0.2 | G15: 0.2 | H15: 0.2 | J15: 0.2 | K15: 2.2 | M15: 2.2
C16: TOTAL | D16: =SUM(D6:D15) -> 19 | E16: =SUM(E6:E15) -> 6.43 | F16: =SUM(F6:F15) -> 0 | G16: =SUM(G6:G15) -> 6.43 | H16: =SUM(H6:H15) -> 2.03 | I16: =SUM(I6:I15) -> 0 | J16: =SUM(J6:J15) -> 2.03 | K16: =SUM(K6:K15) -> 22.13 | ... W16: =SUM(W6:W15) -> 0
B17: Sitao | C17: Altura Bata | D17: 1 | E17: 0.4 | G17: 0.4 | H17: 0.4 | J17: 0.4 | K17: 4 | M17: 4
C18: Ambulong | D18: 4 | E18: 1.25 | G18: 1.25 | H18: 1.25 | J18: 1.25 | K18: 8.5 | M18: 8.5
C19: Gonzales | D19: 1 | E19: 0.1 | G19: 0.1 | H19: 0.1 | J19: 0.1 | K19: 1 | M19: 1
C20: Janopol Occ | D20: 2 | E20: 0.5 | G20: 0.5 | X20: 0.5 Ha Damaged by Krisitne
C21: Janopol Or | D21: 0
C22: Pantay Matanda | D22: 0
C23: San Jose | D23: 13 | E23: 3.75 | G23: 3.75 | H23: 2.85 | J23: 2.85 | K23: 32.6 | M23: 32.6 | X23: 0.9 Damaged by Kristine
C24: Santor | D24: 2 | E24: 0.55 | G24: 0.55 | H24: 0.55 | J24: 0.55 | K24: 5.5 | M24: 5.5
C25: Talaga | D25: 0
C26: Trapiche | D26: 1 | E26: 0.1 | G26: 0.1
C27: TOTAL | D27: =SUM(D17:D26) -> 24 | E27: =SUM(E17:E26) -> 6.65 | F27: =SUM(F17:F26) -> 0 | G27: =SUM(G17:G26) -> 6.65 | H27: =SUM(H17:H26) -> 5.15 | I27: =SUM(I17:I26) -> 0 | J27: =SUM(J17:J26) -> 5.15 | K27: =SUM(K17:K26) -> 51.6 | ... W27: =SUM(W17:W26) -> 0
B28: Squash | C28: Altura Bata | D28: 1 | E28: 0.4 | G28: 0.4 | H28: 0.4 | J28: 0.4 | K28: 10 | M28: 10
C29: Ambulong | D29: 4 | E29: 4.85 | G29: 4.85 | H29: 4.45 | J29: 4.45 | K29: 45 | M29: 45
C30: Gonzales | D30: 1 | E30: 0.5 | G30: 0.5 | H30: 0.5 | J30: 0.5 | K30: 5 | M30: 5
C31: Janopol Occ | D31: 1 | E31: 0.25 | G31: 0.25 | X31: 0.25 Ha Damaged by Kristine
C32: Janopol Or | D32: 1 | E32: 0.1 | G32: 0.1 | H32: 0.1 | J32: 0.1 | K32: 1 | M32: 1
C33: Pantay Matanda | D33: 3 | E33: 0.85 | G33: 0.85 | H33: 0.25 | J33: 0.25 | K33: 2.5 | M33: 2.5
C34: San Jose | D34: 4 | E34: 1.2 | G34: 1.2 | H34: 0.7 | J34: 0.7 | K34: 7 | M34: 7 | X34: 0.5 Ha Damaged by Kristine
C35: Santor | D35: 1 | E35: 0.25 | G35: 0.25 | X35: 0.25 Ha Damaged by Kristine
C36: Talaga | D36: 3 | E36: 1 | G36: 1 | H36: 1 | J36: 1 | K36: 8 | M36: 8
C37: Trapiche | D37: 3 | E37: 0.65 | G37: 0.65 | H37: 0.45 | J37: 0.45 | K37: 4.5 | M37: 4.5
C38: TOTAL | D38: =SUM(D28:D37) -> 22 | E38: =SUM(E28:E37) -> 10.05 | F38: =SUM(F28:F37) -> 0 | G38: =SUM(G28:G37) -> 10.05 | H38: =SUM(H28:H37) -> 7.85 | I38: =SUM(I28:I37) -> 0 | J38: =SUM(J28:J37) -> 7.85 | K38: =SUM(K28:K37) -> 83 | ... W38: =SUM(W28:W37) -> 0
B39: Okra | C39: Altura Bata
C40: Ambulong
C41: Gonzales | D41: 1 | E41: 0.05 | G41: 0.05 | H41: 0.05 | J41: 0.05 | K41: 0.5 | M41: 0.5
...

Sheet Lucido HVCDP
A1: District | B1: Commodity | C1: Barangay | D1: Farmers Served (No.) | E1: Existing Area (ha) | N1: Farmers Served (No.) | O1: Expansion Area (ha) | X1: REMARKS
E2: Area Planted (ha) | H2: Area Harvested (ha) | K2: Production (MT) | O2: Area Planted (ha) | R2: Area Harvested (ha) | U2: Production (MT)
E4: Previous | F4: This Mo. | G4: To Date | H4: Previous | I4: This Mo. | J4: To Date | K4: Previous | L4: This Mo. | M4: To Date | O4: Previous | P4: This Mo. | Q4: To Date | R4: Previous | S4: This Mo. | T4: To Date | U4: Previous | V4: This Mo. | W4: To Date
B5: FRUIT VEGETABLES
B6: Eggplant | C6: Banjo East
C7: Banjo West
C8: Boot
C9: Cale | D9: 3 | E9: 1.15 | G9: =+E9+F9 -> 1.15 | X9: 0.25 ha Damaged by STS Kristine
C10: Darasa
C11: Hidalgo
C12: Maugat | D12: 5 | E12: 4 | G12: =+E12+F12 -> 4 | H12: 0.5 | I12: 0.25 | J12: =SUM(H12+I12) -> 0.75 | K12: 5 | L12: 1.25 | M12: =SUM(K12+L12) -> 6.25 | X12: 1.25 ha- Damaged by STS Kristine
C13: Natatas | D13: 1 | E13: 0.1 | G13: =+E13+F13 -> 0.1
C14: Pantay Bata
C15: Suplang | D15: 2 | E15: 1.3 | G15: =+E15+F15 -> 1.3 | H15: 1.3 | J15: =SUM(H15+I15) -> 1.3 | K15: 13 | M15: =SUM(K15+L15) -> 13
C16: TOTAL | D16: =SUM(D6:D15) -> 11 | E16: =SUM(E6:E15) -> 6.55 | F16: =SUM(F6:F15) -> 0 | G16: =SUM(G6:G15) -> 6.55 | H16: =SUM(H6:H15) -> 1.8 | I16: =SUM(I6:I15) -> 0.25 | J16: =SUM(J6:J15) -> 2.05 | K16: =SUM(K6:K15) -> 18 | ... W16: =SUM(W6:W15) -> 0
B17: Sitao | C17: Banjo East
C18: Banjo West
C19: Boot | D19: 1 | F19: 0.5 | G19: =+E19+F19 -> 0.5
C20: Cale | D20: 10 | E20: 2.35 | F20: 0.55 | G20: =+E20+F20 -> 2.9 | H20: 2.1 | J20: =+H20+I20 -> 2.1 | K20: 20.5 | M20: =+K20+L20 -> 20.5 | X20: 0.25 ha- Damaged by STS Kristine
C21: Darasa | D21: 2 | E21: 0.35 | G21: =+E21+F21 -> 0.35 | H21: 0.35 | J21: =+H21+I21 -> 0.35 | K21: 3.5 | M21: =+K21+L21 -> 3.5
C22: Hidalgo
C23: Maugat | D23: 1 | E23: 0.4 | G23: =+E23+F23 -> 0.4 | H23: 0.4 | J23: =+H23+I23 -> 0.4 | K23: 4 | M23: =+K23+L23 -> 4
C24: Natatas | D24: 6 | E24: 1.7 | G24: =+E24+F24 -> 1.7 | H24: 1.7 | J24: =+H24+I24 -> 1.7 | K24: 17 | M24: =+K24+L24 -> 17
C25: Pantay Bata
C26: Suplang | D26: 5 | E26: 2.15 | G26: =+E26+F26 -> 2.15 | H26: 2.15 | J26: =SUM(H26+I26) -> 2.15 | K26: 21.5 | M26: =SUM(K26+L26) -> 21.5
C27: TOTAL | D27: =SUM(D17:D26) -> 25 | E27: =SUM(E17:E26) -> 6.95 | F27: =SUM(F17:F26) -> 1.05 | G27: =SUM(G17:G26) -> 8 | H27: =SUM(H17:H26) -> 6.7 | I27: =SUM(I17:I26) -> 0 | J27: =SUM(J17:J26) -> 6.7 | K27: =SUM(K17:K26) -> 66.5 | ... W27: =SUM(W17:W26) -> 0
B28: Squash | C28: Banjo East
C29: Banjo West
C30: Boot | D30: 1 | E30: 0.25 | G30: =+E30+F30 -> 0.25
C31: Cale | D31: 9 | E31: 1.1 | G31: =+E31+F31 -> 1.1 | X31: 0.50 ha Damaged by STS Kristine
C32: Darasa | D32: 1 | E32: 0.1 | G32: =+E32+F32 -> 0.1 | H32: 0.1 | J32: =+H32+I32 -> 0.1 | K32: 1 | M32: =+K32+L32 -> 1
C33: Hidalgo
C34: Maugat
C35: Natatas | D35: 3 | E35: 0.57 | G35: =+E35+F35 -> 0.57 | H35: 0.57 | J35: =+H35+I35 -> 0.57 | K35: 4.6 | M35: =+K35+L35 -> 4.6
C36: Pantay Bata | D36: 1 | E36: 0.15 | G36: 0.15 | H36: 0.15 | J36: =+H36+I36 -> 0.15 | K36: 1.5 | M36: =+K36+L36 -> 1.5
C37: Suplang | D37: 1 | E37: 0.15 | G37: =+E37+F37 -> 0.15 | H37: 0.15 | J37: =+H37+I37 -> 0.15 | K37: 1.5 | M37: =+K37+L37 -> 1.5
C38: TOTAL | D38: =SUM(D28:D37) -> 16 | E38: =SUM(E28:E37) -> 2.32 | F38: =SUM(F28:F37) -> 0 | G38: =SUM(G28:G37) -> 2.32 | H38: =SUM(H28:H37) -> 0.97 | I38: =SUM(I28:I37) -> 0 | J38: =SUM(J28:J37) -> 0.97 | K38: =SUM(K28:K37) -> 8.6 | ... W38: =SUM(W28:W37) -> 0
B39: Okra | C39: Banjo East
C40: Banjo West
C41: Boot
...

Sheet Rimas HVCDP
A1: District | B1: Commodity | C1: Barangay | D1: Farmers Served (No.) | E1: Existing Area (ha) | N1: Farmers Served (No.) | O1: Expansion Area (ha) | X1: REMARKS
E2: Area Planted (ha) | H2: Area Harvested (ha) | K2: Production (MT) | O2: Area Planted (ha) | R2: Area Harvested (ha) | U2: Production (MT)
E4: Previous | F4: This Mo. | G4: To Date | H4: Previous | I4: This Mo. | J4: To Date | K4: Previous | L4: This Mo. | M4: To Date | O4: Previous | P4: This Mo. | Q4: To Date | R4: Previous | S4: This Mo. | T4: To Date | U4: Previous | V4: This Mo. | W4: To Date
B5: FRUIT VEGETABLES | X5: Affected by STS Kristine
B6: Eggplant | C6: Bagbag
C7: Bagumbayan
C8: Balele
C9: Laurel
C10: Mabini | D10: 3 | E10: 2.1 | G10: 2.1 | H10: 0.3 | J10: 0.3 | K10: 1.2 | M10: 1.2
C11: Maria Paz
C12: Pagaspas
C13: Tinurik
C14: Ulango | D14: 1 | E14: 0.5 | G14: 0.5
C15: Wawa
C16: TOTAL | D16: =SUM(D6:D15) -> 4 | E16: =SUM(E6:E15) -> 2.6 | F16: =SUM(F6:F15) -> 0 | G16: =SUM(G6:G15) -> 2.6 | H16: =SUM(H6:H15) -> 0.3 | I16: =SUM(I6:I15) -> 0 | J16: =SUM(J6:J15) -> 0.3 | K16: =SUM(K6:K15) -> 1.2 | ... W16: =SUM(W6:W15) -> 0
B17: Sitao | C17: Bagbag | D17: 4 | E17: 1.8 | G17: 1.8 | H17: 0.5 | J17: 0.5 | K17: 2 | M17: 2
C18: Bagumbayan | D18: 1 | E18: 0.05 | G18: 0.05 | H18: 0.05 | J18: 0.05 | K18: 0.2 | M18: 0.2
C19: Balele | D19: 4 | E19: 1.25 | G19: 1.25 | H19: 1 | J19: 1 | K19: 5 | M19: 5
C20: Laurel
C21: Mabini | D21: 2 | E21: 0.75 | G21: 0.75 | H21: 0.75 | J21: 0.75 | K21: 3 | M21: 3
C22: Maria Paz | D22: 6 | E22: 2.35 | G22: 2.35 | H22: 2.35 | J22: 2.35 | K22: 11.75 | M22: 11.75
C23: Pagaspas
C24: Tinurik
C25: Ulango | D25: 2 | E25: 0.75 | G25: 0.75 | H25: 0.25 | J25: 0.25 | K25: 1 | M25: 1
C26: Wawa | D26: 1 | E26: 0.25 | G26: 0.25
C27: TOTAL | D27: =SUM(D17:D26) -> 20 | E27: =SUM(E17:E26) -> 7.2 | F27: =SUM(F17:F26) -> 0 | G27: =SUM(G17:G26) -> 7.2 | H27: =SUM(H17:H26) -> 4.9 | I27: =SUM(I17:I26) -> 0 | J27: =SUM(J17:J26) -> 4.9 | K27: =SUM(K17:K26) -> 22.95 | ... W27: =SUM(W17:W26) -> 0
B28: Squash | C28: Bagbag
C29: Bagumbayan | D29: 2 | E29: 0.55 | G29: 0.55 | H29: 0.55 | J29: 0.55 | K29: 2.75 | M29: 2.75
C30: Balele | D30: 2 | E30: 0.8 | G30: 0.8 | H30: 0.8 | J30: 0.8 | K30: 4.8 | M30: 4.8
C31: Laurel | D31: 2 | E31: 0.5 | G31: 0.5 | H31: 0.5 | J31: 0.5 | K31: 3 | M31: 3
C32: Mabini
C33: Maria Paz | D33: 21 | E33: 0.5 | G33: 0.5 | H33: 0.5 | J33: 0.5 | K33: 3 | M33: 3
C34: Pagaspas
C35: Tinurik
C36: Ulango
C37: Wawa | D37: 1 | E37: 0.25 | G37: 0.25 | H37: 0.25 | J37: 0.25 | K37: 1.5 | M37: 1.5
C38: TOTAL | D38: =SUM(D28:D37) -> 28 | E38: =SUM(E28:E37) -> 2.6 | F38: =SUM(F28:F37) -> 0 | G38: =SUM(G28:G37) -> 2.6 | H38: =SUM(H28:H37) -> 2.6 | I38: =SUM(I28:I37) -> 0 | J38: =SUM(J28:J37) -> 2.6 | K38: =SUM(K28:K37) -> 15.05 | ... W38: =SUM(W28:W37) -> 0
B39: Okra | C39: Bagbag
C40: Bagumbayan
C41: Balele | D41: 2 | E41: 1 | G41: 1 | H41: 1 | J41: 1 | K41: 5 | M41: 5
...

Sheet Consolidation HVCDP
A1: District | B1: Commodity | C1: Barangay | D1: Farmers Served (No.) | E1: Existing Area (ha) | N1: Farmers Served (No.) | O1: Expansion Area (ha) | X1: REMARKS
E2: Area Planted (ha) | H2: Area Harvested (ha) | K2: Production (MT) | O2: Area Planted (ha) | R2: Area Harvested (ha) | U2: Production (MT)
E4: Previous | F4: This Mo. | G4: To Date | H4: Previous | I4: This Mo. | J4: To Date | K4: Previous | L4: This Mo. | M4: To Date | O4: Previous | P4: This Mo. | Q4: To Date | R4: Previous | S4: This Mo. | T4: To Date | U4: Previous | V4: This Mo. | W4: To Date
A5: III | B5: FRUIT VEGETABLES
B6: Eggplant | C6: =COUNTA('Piamonte HVCDP'!D6:D15)+COUNTA('Requizo HVCDP'!D6:D15)+COUNTA('Lucido HVCDP'!D6:D15)+COUNTA('Rimas HVCDP'!D6:D15) -> 17 | D6: =SUM('Piamonte HVCDP'!D16+'Requizo HVCDP'!D16+'Lucido HVCDP'!D16+'Rimas HVCDP'!D16) -> 52 | E6: =SUM('Piamonte HVCDP'!E16+'Requizo HVCDP'!E16+'Lucido HVCDP'!E16+'Rimas HVCDP'!E16) -> 24.03 | F6: =SUM('Piamonte HVCDP'!F16+'Requizo HVCDP'!F16+'Lucido HVCDP'!F16+'Rimas HVCDP'!F16) -> 2.1 | G6: =SUM('Piamonte HVCDP'!G16+'Requizo HVCDP'!G16+'Lucido HVCDP'!G16+'Rimas HVCDP'!G16) -> 26.13 | H6: =SUM('Piamonte HVCDP'!H16+'Requizo HVCDP'!H16+'Lucido HVCDP'!H16+'Rimas HVCDP'!H16) -> 11.28 | I6: =SUM('Piamonte HVCDP'!I16+'Requizo HVCDP'!I16+'Lucido HVCDP'!I16+'Rimas HVCDP'!I16) -> 0.65 | J6: =SUM('Piamonte HVCDP'!J16+'Requizo HVCDP'!J16+'Lucido HVCDP'!J16+'Rimas HVCDP'!J16) -> 11.93 | K6: =SUM('Piamonte HVCDP'!K16+'Requizo HVCDP'!K16+'Lucido HVCDP'!K16+'Rimas HVCDP'!K16) -> 113.23 | ... W6: =SUM('Piamonte HVCDP'!W16+'Requizo HVCDP'!W16+'Lucido HVCDP'!W16+'Rimas HVCDP'!W16) -> 0
B7: Sitao | C7: =COUNTA('Piamonte HVCDP'!D17:D26)+COUNTA('Requizo HVCDP'!D17:D26)+COUNTA('Lucido HVCDP'!D17:D26)+COUNTA('Rimas HVCDP'!D17:D26) -> 29 | D7: =SUM('Piamonte HVCDP'!D27+'Requizo HVCDP'!D27+'Lucido HVCDP'!D27+'Rimas HVCDP'!D27) -> 129 | E7: =SUM('Piamonte HVCDP'!E27+'Requizo HVCDP'!E27+'Lucido HVCDP'!E27+'Rimas HVCDP'!E27) -> 44.62 | F7: =SUM('Piamonte HVCDP'!F27+'Requizo HVCDP'!F27+'Lucido HVCDP'!F27+'Rimas HVCDP'!F27) -> 2.3 | G7: =SUM('Piamonte HVCDP'!G27+'Requizo HVCDP'!G27+'Lucido HVCDP'!G27+'Rimas HVCDP'!G27) -> 46.92 | H7: =SUM('Piamonte HVCDP'!H27+'Requizo HVCDP'!H27+'Lucido HVCDP'!H27+'Rimas HVCDP'!H27) -> 30.72 | I7: =SUM('Piamonte HVCDP'!I27+'Requizo HVCDP'!I27+'Lucido HVCDP'!I27+'Rimas HVCDP'!I27) -> 0 | J7: =SUM('Piamonte HVCDP'!J27+'Requizo HVCDP'!J27+'Lucido HVCDP'!J27+'Rimas HVCDP'!J27) -> 30.72 | K7: =SUM('Piamonte HVCDP'!K27+'Requizo HVCDP'!K27+'Lucido HVCDP'!K27+'Rimas HVCDP'!K27) -> 232.37 | ... W7: =SUM('Piamonte HVCDP'!W27+'Requizo HVCDP'!W27+'Lucido HVCDP'!W27+'Rimas HVCDP'!W27) -> 0
B8: Squash | C8: =COUNTA('Piamonte HVCDP'!D28:D37,'Requizo HVCDP'!D28:D37,'Lucido HVCDP'!D28:D37,'Rimas HVCDP'!D28:D37) -> 27 | D8: =SUM('Piamonte HVCDP'!D38+'Requizo HVCDP'!D38+'Lucido HVCDP'!D38+'Rimas HVCDP'!D38) -> 95 | E8: =SUM('Piamonte HVCDP'!E38+'Requizo HVCDP'!E38+'Lucido HVCDP'!E38+'Rimas HVCDP'!E38) -> 26.57 | F8: =SUM('Piamonte HVCDP'!F38+'Requizo HVCDP'!F38+'Lucido HVCDP'!F38+'Rimas HVCDP'!F38) -> 1.2 | G8: =SUM('Piamonte HVCDP'!G38+'Requizo HVCDP'!G38+'Lucido HVCDP'!G38+'Rimas HVCDP'!G38) -> 27.77 | H8: =SUM('Piamonte HVCDP'!H38+'Requizo HVCDP'!H38+'Lucido HVCDP'!H38+'Rimas HVCDP'!H38) -> 17.12 | I8: =SUM('Piamonte HVCDP'!I38+'Requizo HVCDP'!I38+'Lucido HVCDP'!I38+'Rimas HVCDP'!I38) -> 0 | J8: =SUM('Piamonte HVCDP'!J38+'Requizo HVCDP'!J38+'Lucido HVCDP'!J38+'Rimas HVCDP'!J38) -> 17.12 | K8: =SUM('Piamonte HVCDP'!K38+'Requizo HVCDP'!K38+'Lucido HVCDP'!K38+'Rimas HVCDP'!K38) -> 156.45 | ... W8: =SUM('Piamonte HVCDP'!W38+'Requizo HVCDP'!W38+'Lucido HVCDP'!W38+'Rimas HVCDP'!W38) -> 0
B9: Okra | C9: =COUNTA('Piamonte HVCDP'!D39:D48,'Requizo HVCDP'!D39:D48,'Lucido HVCDP'!D39:D48,'Rimas HVCDP'!D39:D48) -> 12 | D9: =SUM('Piamonte HVCDP'!D49+'Requizo HVCDP'!D49+'Lucido HVCDP'!D49+'Rimas HVCDP'!D49) -> 52 | E9: =SUM('Piamonte HVCDP'!E49+'Requizo HVCDP'!E49+'Lucido HVCDP'!E49+'Rimas HVCDP'!E49) -> 17.17 | F9: =SUM('Piamonte HVCDP'!F49+'Requizo HVCDP'!F49+'Lucido HVCDP'!F49+'Rimas HVCDP'!F49) -> 0 | G9: =SUM('Piamonte HVCDP'!G49+'Requizo HVCDP'!G49+'Lucido HVCDP'!G49+'Rimas HVCDP'!G49) -> 17.17 | H9: =SUM('Piamonte HVCDP'!H49+'Requizo HVCDP'!H49+'Lucido HVCDP'!H49+'Rimas HVCDP'!H49) -> 13.92 | I9: =SUM('Piamonte HVCDP'!I49+'Requizo HVCDP'!I49+'Lucido HVCDP'!I49+'Rimas HVCDP'!I49) -> 0.5 | J9: =SUM('Piamonte HVCDP'!J49+'Requizo HVCDP'!J49+'Lucido HVCDP'!J49+'Rimas HVCDP'!J49) -> 14.42 | K9: =SUM('Piamonte HVCDP'!K49+'Requizo HVCDP'!K49+'Lucido HVCDP'!K49+'Rimas HVCDP'!K49) -> 106.78 | ... W9: =SUM('Piamonte HVCDP'!W49+'Requizo HVCDP'!W49+'Lucido HVCDP'!W49+'Rimas HVCDP'!W49) -> 0
B10: Patola | C10: =COUNTA('Piamonte HVCDP'!D50:D59,'Requizo HVCDP'!D50:D59,'Lucido HVCDP'!D50:D59,'Rimas HVCDP'!D50:D59) -> 11 | D10: =SUM('Piamonte HVCDP'!D60+'Requizo HVCDP'!D60+'Lucido HVCDP'!D60+'Rimas HVCDP'!D60) -> 35 | E10: =SUM('Piamonte HVCDP'!E60+'Requizo HVCDP'!E60+'Lucido HVCDP'!E60+'Rimas HVCDP'!E60) -> 11.13 | F10: =SUM('Piamonte HVCDP'!F60+'Requizo HVCDP'!F60+'Lucido HVCDP'!F60+'Rimas HVCDP'!F60) -> 0.5 | G10: =SUM('Piamonte HVCDP'!G60+'Requizo HVCDP'!G60+'Lucido HVCDP'!G60+'Rimas HVCDP'!G60) -> 11.63 | H10: =SUM('Piamonte HVCDP'!H60+'Requizo HVCDP'!H60+'Lucido HVCDP'!H60+'Rimas HVCDP'!H60) -> 5.7 | I10: =SUM('Piamonte HVCDP'!I60+'Requizo HVCDP'!I60+'Lucido HVCDP'!I60+'Rimas HVCDP'!I60) -> 0 | J10: =SUM('Piamonte HVCDP'!J60+'Requizo HVCDP'!J60+'Lucido HVCDP'!J60+'Rimas HVCDP'!J60) -> 5.7 | K10: =SUM('Piamonte HVCDP'!K60+'Requizo HVCDP'!K60+'Lucido HVCDP'!K60+'Rimas HVCDP'!K60) -> 42.8 | ... W10: =SUM('Piamonte HVCDP'!W60+'Requizo HVCDP'!W60+'Lucido HVCDP'!W60+'Rimas HVCDP'!W60) -> 0
B11: Sigarilyas | C11: =COUNTA('Piamonte HVCDP'!D61:D70,'Requizo HVCDP'!D61:D70,'Lucido HVCDP'!D61:D70,'Rimas HVCDP'!D61:D70) -> 14 | D11: =SUM('Piamonte HVCDP'!D71+'Requizo HVCDP'!D71+'Lucido HVCDP'!D71+'Rimas HVCDP'!D71) -> 54 | E11: =SUM('Piamonte HVCDP'!E71+'Requizo HVCDP'!E71+'Lucido HVCDP'!E71+'Rimas HVCDP'!E71) -> 24.38 | F11: =SUM('Piamonte HVCDP'!F71+'Requizo HVCDP'!F71+'Lucido HVCDP'!F71+'Rimas HVCDP'!F71) -> 0 | G11: =SUM('Piamonte HVCDP'!G71+'Requizo HVCDP'!G71+'Lucido HVCDP'!G71+'Rimas HVCDP'!G71) -> 24.38 | H11: =SUM('Piamonte HVCDP'!H71+'Requizo HVCDP'!H71+'Lucido HVCDP'!H71+'Rimas HVCDP'!H71) -> 18.21 | I11: =SUM('Piamonte HVCDP'!I71+'Requizo HVCDP'!I71+'Lucido HVCDP'!I71+'Rimas HVCDP'!I71) -> 0 | J11: =SUM('Piamonte HVCDP'!J71+'Requizo HVCDP'!J71+'Lucido HVCDP'!J71+'Rimas HVCDP'!J71) -> 18.21 | K11: =SUM('Piamonte HVCDP'!K71+'Requizo HVCDP'!K71+'Lucido HVCDP'!K71+'Rimas HVCDP'!K71) -> 80.23 | ... W11: =SUM('Piamonte HVCDP'!W71+'Requizo HVCDP'!W71+'Lucido HVCDP'!W71+'Rimas HVCDP'!W71) -> 0
B12: Upo | C12: =COUNTA('Piamonte HVCDP'!D72:D81,'Requizo HVCDP'!D72:D81,'Lucido HVCDP'!D72:D81,'Rimas HVCDP'!D72:D81) -> 12 | D12: =SUM('Piamonte HVCDP'!D82+'Requizo HVCDP'!D82+'Lucido HVCDP'!D82+'Rimas HVCDP'!D82) -> 30 | E12: =SUM('Piamonte HVCDP'!E82+'Requizo HVCDP'!E82+'Lucido HVCDP'!E82+'Rimas HVCDP'!E82) -> 9 | F12: =SUM('Piamonte HVCDP'!F82+'Requizo HVCDP'!F82+'Lucido HVCDP'!F82+'Rimas HVCDP'!F82) -> 2.2 | G12: =SUM('Piamonte HVCDP'!G82+'Requizo HVCDP'!G82+'Lucido HVCDP'!G82+'Rimas HVCDP'!G82) -> 11.2 | H12: =SUM('Piamonte HVCDP'!H82+'Requizo HVCDP'!H82+'Lucido HVCDP'!H82+'Rimas HVCDP'!H82) -> 5.6 | I12: =SUM('Piamonte HVCDP'!I82+'Requizo HVCDP'!I82+'Lucido HVCDP'!I82+'Rimas HVCDP'!I82) -> 0.44 | J12: =SUM('Piamonte HVCDP'!J82+'Requizo HVCDP'!J82+'Lucido HVCDP'!J82+'Rimas HVCDP'!J82) -> 6.04 | K12: =SUM('Piamonte HVCDP'!K82+'Requizo HVCDP'!K82+'Lucido HVCDP'!K82+'Rimas HVCDP'!K82) -> 44.2 | ... W12: =SUM('Piamonte HVCDP'!W82+'Requizo HVCDP'!W82+'Lucido HVCDP'!W82+'Rimas HVCDP'!W82) -> 0
B13: Ampalaya | C13: =COUNTA('Piamonte HVCDP'!D83:D92,'Requizo HVCDP'!D83:D92,'Lucido HVCDP'!D83:D92,'Rimas HVCDP'!D83:D92) -> 18 | D13: =SUM('Piamonte HVCDP'!D93+'Requizo HVCDP'!D93+'Lucido HVCDP'!D93+'Rimas HVCDP'!D93) -> 53 | E13: =SUM('Piamonte HVCDP'!E93+'Requizo HVCDP'!E93+'Lucido HVCDP'!E93+'Rimas HVCDP'!E93) -> 23.25 | F13: =SUM('Piamonte HVCDP'!F93+'Requizo HVCDP'!F93+'Lucido HVCDP'!F93+'Rimas HVCDP'!F93) -> 2.7 | G13: =SUM('Piamonte HVCDP'!G93+'Requizo HVCDP'!G93+'Lucido HVCDP'!G93+'Rimas HVCDP'!G93) -> 25.95 | H13: =SUM('Piamonte HVCDP'!H93+'Requizo HVCDP'!H93+'Lucido HVCDP'!H93+'Rimas HVCDP'!H93) -> 16.88 | I13: =SUM('Piamonte HVCDP'!I93+'Requizo HVCDP'!I93+'Lucido HVCDP'!I93+'Rimas HVCDP'!I93) -> 0 | J13: =SUM('Piamonte HVCDP'!J93+'Requizo HVCDP'!J93+'Lucido HVCDP'!J93+'Rimas HVCDP'!J93) -> 16.88 | K13: =SUM('Piamonte HVCDP'!K93+'Requizo HVCDP'!K93+'Lucido HVCDP'!K93+'Rimas HVCDP'!K93) -> 99.35 | ... W13: =SUM('Piamonte HVCDP'!W93+'Requizo HVCDP'!W93+'Lucido HVCDP'!W93+'Rimas HVCDP'!W93) -> 0
B14: Pipino | C14: =COUNTA('Piamonte HVCDP'!D94:D103,'Requizo HVCDP'!D94:D103,'Lucido HVCDP'!D94:D103,'Rimas HVCDP'!D94:D103) -> 1 | D14: =SUM('Piamonte HVCDP'!D104+'Requizo HVCDP'!D104+'Lucido HVCDP'!D104+'Rimas HVCDP'!D104) -> 6 | E14: =SUM('Piamonte HVCDP'!E104+'Requizo HVCDP'!E104+'Lucido HVCDP'!E104+'Rimas HVCDP'!E104) -> 1.9 | F14: =SUM('Piamonte HVCDP'!F104+'Requizo HVCDP'!F104+'Lucido HVCDP'!F104+'Rimas HVCDP'!F104) -> 0 | G14: =SUM('Piamonte HVCDP'!G104+'Requizo HVCDP'!G104+'Lucido HVCDP'!G104+'Rimas HVCDP'!G104) -> 1.9 | H14: =SUM('Piamonte HVCDP'!H104+'Requizo HVCDP'!H104+'Lucido HVCDP'!H104+'Rimas HVCDP'!H104) -> 0.3 | I14: =SUM('Piamonte HVCDP'!I104+'Requizo HVCDP'!I104+'Lucido HVCDP'!I104+'Rimas HVCDP'!I104) -> 0 | J14: =SUM('Piamonte HVCDP'!J104+'Requizo HVCDP'!J104+'Lucido HVCDP'!J104+'Rimas HVCDP'!J104) -> 0.3 | K14: =SUM('Piamonte HVCDP'!K104+'Requizo HVCDP'!K104+'Lucido HVCDP'!K104+'Rimas HVCDP'!K104) -> 0.45 | ... W14: =SUM('Piamonte HVCDP'!W104+'Requizo HVCDP'!W104+'Lucido HVCDP'!W104+'Rimas HVCDP'!W104) -> 0
B15: Sili | C15: =COUNTA('Piamonte HVCDP'!D105:D114,'Requizo HVCDP'!D105:D114,'Lucido HVCDP'!D105:D114,'Rimas HVCDP'!D105:D114) -> 9 | D15: =SUM('Piamonte HVCDP'!D115+'Requizo HVCDP'!D115+'Lucido HVCDP'!D115+'Rimas HVCDP'!D115) -> 15 | E15: =SUM('Piamonte HVCDP'!E115+'Requizo HVCDP'!E115+'Lucido HVCDP'!E115+'Rimas HVCDP'!E115) -> 6.05 | F15: =SUM('Piamonte HVCDP'!F115+'Requizo HVCDP'!F115+'Lucido HVCDP'!F115+'Rimas HVCDP'!F115) -> 0 | G15: =SUM('Piamonte HVCDP'!G115+'Requizo HVCDP'!G115+'Lucido HVCDP'!G115+'Rimas HVCDP'!G115) -> 6.05 | H15: =SUM('Piamonte HVCDP'!H115+'Requizo HVCDP'!H115+'Lucido HVCDP'!H115+'Rimas HVCDP'!H115) -> 1.25 | I15: =SUM('Piamonte HVCDP'!I115+'Requizo HVCDP'!I115+'Lucido HVCDP'!I115+'Rimas HVCDP'!I115) -> 0.19 | J15: =SUM('Piamonte HVCDP'!J115+'Requizo HVCDP'!J115+'Lucido HVCDP'!J115+'Rimas HVCDP'!J115) -> 1.44 | K15: =SUM('Piamonte HVCDP'!K115+'Requizo HVCDP'!K115+'Lucido HVCDP'!K115+'Rimas HVCDP'!K115) -> 9.9 | ... W15: =SUM('Piamonte HVCDP'!W115+'Requizo HVCDP'!W115+'Lucido HVCDP'!W115+'Rimas HVCDP'!W115) -> 0
B16: Beans | C16: =COUNTA('Piamonte HVCDP'!D116:D125,'Requizo HVCDP'!D116:D125,'Lucido HVCDP'!D127:D136,'Rimas HVCDP'!D116:D125) -> 8 | D16: =SUM('Piamonte HVCDP'!D126+'Requizo HVCDP'!D126+'Lucido HVCDP'!D137+'Rimas HVCDP'!D126) -> 14 | E16: =SUM('Piamonte HVCDP'!E126+'Requizo HVCDP'!E126+'Lucido HVCDP'!E137+'Rimas HVCDP'!E126) -> 5.53 | F16: =SUM('Piamonte HVCDP'!F126+'Requizo HVCDP'!F126+'Lucido HVCDP'!F137+'Rimas HVCDP'!F126) -> 0.25 | G16: =SUM('Piamonte HVCDP'!G126+'Requizo HVCDP'!G126+'Lucido HVCDP'!G137+'Rimas HVCDP'!G126) -> 5.78 | H16: =SUM('Piamonte HVCDP'!H126+'Requizo HVCDP'!H126+'Lucido HVCDP'!H137+'Rimas HVCDP'!H126) -> 2.53 | I16: =SUM('Piamonte HVCDP'!I126+'Requizo HVCDP'!I126+'Lucido HVCDP'!I137+'Rimas HVCDP'!I126) -> 0 | J16: =SUM('Piamonte HVCDP'!J126+'Requizo HVCDP'!J126+'Lucido HVCDP'!J137+'Rimas HVCDP'!J126) -> 2.53 | K16: =SUM('Piamonte HVCDP'!K126+'Requizo HVCDP'!K126+'Lucido HVCDP'!K137+'Rimas HVCDP'!K126) -> 16.7 | ... W16: =SUM('Piamonte HVCDP'!W126+'Requizo HVCDP'!W126+'Lucido HVCDP'!W137+'Rimas HVCDP'!W126) -> 0
B17: Paayap | C17: =COUNTA('Piamonte HVCDP'!D127:D136,'Requizo HVCDP'!D127:D136,'Lucido HVCDP'!D160:D169,'Rimas HVCDP'!D127:D136) -> 7 | D17: =SUM('Piamonte HVCDP'!D137+'Requizo HVCDP'!D137+'Lucido HVCDP'!D170+'Rimas HVCDP'!D137) -> 11 | E17: =SUM('Piamonte HVCDP'!E137+'Requizo HVCDP'!E137+'Lucido HVCDP'!E170+'Rimas HVCDP'!E137) -> 2.75 | F17: =SUM('Piamonte HVCDP'!F137+'Requizo HVCDP'!F137+'Lucido HVCDP'!F170+'Rimas HVCDP'!F137) -> 0.7 | G17: =SUM('Piamonte HVCDP'!G137+'Requizo HVCDP'!G137+'Lucido HVCDP'!G170+'Rimas HVCDP'!G137) -> 3.45 | H17: =SUM('Piamonte HVCDP'!H137+'Requizo HVCDP'!H137+'Lucido HVCDP'!H170+'Rimas HVCDP'!H137) -> 1.6 | I17: =SUM('Piamonte HVCDP'!I137+'Requizo HVCDP'!I137+'Lucido HVCDP'!I170+'Rimas HVCDP'!I137) -> 0 | J17: =SUM('Piamonte HVCDP'!J137+'Requizo HVCDP'!J137+'Lucido HVCDP'!J170+'Rimas HVCDP'!J137) -> 1.6 | K17: =SUM('Piamonte HVCDP'!K137+'Requizo HVCDP'!K137+'Lucido HVCDP'!K170+'Rimas HVCDP'!K137) -> 16 | ... W17: =SUM('Piamonte HVCDP'!W137+'Requizo HVCDP'!W137+'Lucido HVCDP'!W170+'Rimas HVCDP'!W137) -> 0
B18: Tomato | C18: =COUNTA('Piamonte HVCDP'!D138:D147,'Requizo HVCDP'!D138:D147,'Lucido HVCDP'!D171:D180,'Rimas HVCDP'!D138:D147) -> 10 | D18: =SUM('Piamonte HVCDP'!D148+'Requizo HVCDP'!D148+'Lucido HVCDP'!D181+'Rimas HVCDP'!D148) -> 23 | E18: =SUM('Piamonte HVCDP'!E148+'Requizo HVCDP'!E148+'Lucido HVCDP'!E181+'Rimas HVCDP'!E148) -> 7.9 | F18: =SUM('Piamonte HVCDP'!F148+'Requizo HVCDP'!F148+'Lucido HVCDP'!F181+'Rimas HVCDP'!F148) -> 3.4 | G18: =SUM('Piamonte HVCDP'!G148+'Requizo HVCDP'!G148+'Lucido HVCDP'!G181+'Rimas HVCDP'!G148) -> 11.3 | H18: =SUM('Piamonte HVCDP'!H148+'Requizo HVCDP'!H148+'Lucido HVCDP'!H181+'Rimas HVCDP'!H148) -> 4.57 | I18: =SUM('Piamonte HVCDP'!I148+'Requizo HVCDP'!I148+'Lucido HVCDP'!I181+'Rimas HVCDP'!I148) -> 0.19 | J18: =SUM('Piamonte HVCDP'!J148+'Requizo HVCDP'!J148+'Lucido HVCDP'!J181+'Rimas HVCDP'!J148) -> 4.76 | K18: =SUM('Piamonte HVCDP'!K148+'Requizo HVCDP'!K148+'Lucido HVCDP'!K181+'Rimas HVCDP'!K148) -> 52 | ... W18: =SUM('Piamonte HVCDP'!W148+'Requizo HVCDP'!W148+'Lucido HVCDP'!W181+'Rimas HVCDP'!W148) -> 0
B19: Patani | C19: =COUNTA('Requizo HVCDP'!D149,'Lucido HVCDP'!D138:D147,'Rimas HVCDP'!D149) -> 3 | D19: =SUM('Requizo HVCDP'!D159+'Lucido HVCDP'!D148+'Rimas HVCDP'!D150) -> 5 | E19: =SUM('Requizo HVCDP'!E159+'Lucido HVCDP'!E148+'Rimas HVCDP'!E150) -> 1.05 | F19: =SUM('Requizo HVCDP'!F159+'Lucido HVCDP'!F148+'Rimas HVCDP'!F150) -> 0 | G19: =SUM('Requizo HVCDP'!G159+'Lucido HVCDP'!G148+'Rimas HVCDP'!G150) -> 1.05 | H19: =SUM('Requizo HVCDP'!H159+'Lucido HVCDP'!H148+'Rimas HVCDP'!H150) -> 0.65 | I19: =SUM('Requizo HVCDP'!I159+'Lucido HVCDP'!I148+'Rimas HVCDP'!I150) -> 0 | J19: =SUM('Requizo HVCDP'!J159+'Lucido HVCDP'!J148+'Rimas HVCDP'!J150) -> 0.65 | K19: =SUM('Requizo HVCDP'!K159+'Lucido HVCDP'!K148+'Rimas HVCDP'!K150) -> 6.5 | ... W19: =SUM('Requizo HVCDP'!W159+'Lucido HVCDP'!W148+'Rimas HVCDP'!W150) -> 0
B20: Mungbean | C20: =COUNTA('Lucido HVCDP'!D116:D125) -> 0 | D20: =SUM('Lucido HVCDP'!D126) -> 0 | E20: =SUM('Lucido HVCDP'!E126) -> 0 | F20: =SUM('Lucido HVCDP'!F126) -> 0 | G20: =SUM('Lucido HVCDP'!G126) -> 0 | H20: =SUM('Lucido HVCDP'!H126) -> 0 | I20: =SUM('Lucido HVCDP'!I126) -> 0 | J20: =SUM('Lucido HVCDP'!J126) -> 0 | K20: =SUM('Lucido HVCDP'!K126) -> 0 | ... W20: =SUM('Lucido HVCDP'!W126) -> 0
B21: INDUSTRIAL CROPS
B22: Banana | C22: =COUNTA('Piamonte HVCDP'!D150:D159,'Requizo HVCDP'!D162:D171,'Lucido HVCDP'!D183:D192,'Rimas HVCDP'!D153:D162) -> 40 | D22: =SUM('Piamonte HVCDP'!D160+'Requizo HVCDP'!D172+'Lucido HVCDP'!D193+'Rimas HVCDP'!D163) -> 917 | E22: =SUM('Piamonte HVCDP'!E160+'Requizo HVCDP'!E172+'Lucido HVCDP'!E193+'Rimas HVCDP'!E163) -> 336.7747 | F22: =SUM('Piamonte HVCDP'!F160+'Requizo HVCDP'!F172+'Lucido HVCDP'!F193+'Rimas HVCDP'!F163) -> 0 | G22: =SUM('Piamonte HVCDP'!G160+'Requizo HVCDP'!G172+'Lucido HVCDP'!G193+'Rimas HVCDP'!G163) -> 336.7747 | H22: =SUM('Piamonte HVCDP'!H160+'Requizo HVCDP'!H172+'Lucido HVCDP'!H193+'Rimas HVCDP'!H163) -> 8.4 | I22: =SUM('Piamonte HVCDP'!I160+'Requizo HVCDP'!I172+'Lucido HVCDP'!I193+'Rimas HVCDP'!I163) -> 0 | J22: =SUM('Piamonte HVCDP'!J160+'Requizo HVCDP'!J172+'Lucido HVCDP'!J193+'Rimas HVCDP'!J163) -> 8.4 | K22: =SUM('Piamonte HVCDP'!K160+'Requizo HVCDP'!K172+'Lucido HVCDP'!K193+'Rimas HVCDP'!K163) -> 93.65 | ... W22: =SUM('Piamonte HVCDP'!W160+'Requizo HVCDP'!W172+'Lucido HVCDP'!W193+'Rimas HVCDP'!W163) -> 0
B23: Cacao | C23: =COUNTA('Piamonte HVCDP'!D161:D170,'Requizo HVCDP'!D173:D182,'Lucido HVCDP'!D194:D203,'Rimas HVCDP'!D164:D173) -> 40 | D23: =SUM('Piamonte HVCDP'!D171+'Requizo HVCDP'!D183+'Lucido HVCDP'!D204+'Rimas HVCDP'!D174) -> 41 | E23: =SUM('Piamonte HVCDP'!E171+'Requizo HVCDP'!E183+'Lucido HVCDP'!E204+'Rimas HVCDP'!E174) -> 16.414 | F23: =SUM('Piamonte HVCDP'!F171+'Requizo HVCDP'!F183+'Lucido HVCDP'!F204+'Rimas HVCDP'!F174) -> 0 | G23: =SUM('Piamonte HVCDP'!G171+'Requizo HVCDP'!G183+'Lucido HVCDP'!G204+'Rimas HVCDP'!G174) -> 16.414 | H23: =SUM('Piamonte HVCDP'!H171+'Requizo HVCDP'!H183+'Lucido HVCDP'!H204+'Rimas HVCDP'!H174) -> 0 | I23: =SUM('Piamonte HVCDP'!I171+'Requizo HVCDP'!I183+'Lucido HVCDP'!I204+'Rimas HVCDP'!I174) -> 0 | J23: =SUM('Piamonte HVCDP'!J171+'Requizo HVCDP'!J183+'Lucido HVCDP'!J204+'Rimas HVCDP'!J174) -> 0 | K23: =SUM('Piamonte HVCDP'!K171+'Requizo HVCDP'!K183+'Lucido HVCDP'!K204+'Rimas HVCDP'!K174) -> 0 | ... W23: =SUM('Piamonte HVCDP'!W171+'Requizo HVCDP'!W183+'Lucido HVCDP'!W204+'Rimas HVCDP'!W174) -> 0
B24: Coffee | C24: =COUNTA('Piamonte HVCDP'!D172,'Requizo HVCDP'!D184:D187,'Lucido HVCDP'!D205,'Rimas HVCDP'!D175:D177) -> 6 | D24: =SUM('Piamonte HVCDP'!D173+'Requizo HVCDP'!D188+'Lucido HVCDP'!D206+'Rimas HVCDP'!D178) -> 3 | E24: =SUM('Piamonte HVCDP'!E173+'Requizo HVCDP'!E188+'Lucido HVCDP'!E206+'Rimas HVCDP'!E178) -> 3.7 | F24: =SUM('Piamonte HVCDP'!F173+'Requizo HVCDP'!F188+'Lucido HVCDP'!F206+'Rimas HVCDP'!F178) -> 0 | G24: =SUM('Piamonte HVCDP'!G173+'Requizo HVCDP'!G188+'Lucido HVCDP'!G206+'Rimas HVCDP'!G178) -> 3.7 | H24: =SUM('Piamonte HVCDP'!H173+'Requizo HVCDP'!H188+'Lucido HVCDP'!H206+'Rimas HVCDP'!H178) -> 0 | I24: =SUM('Piamonte HVCDP'!I173+'Requizo HVCDP'!I188+'Lucido HVCDP'!I206+'Rimas HVCDP'!I178) -> 0 | J24: =SUM('Piamonte HVCDP'!J173+'Requizo HVCDP'!J188+'Lucido HVCDP'!J206+'Rimas HVCDP'!J178) -> 0 | K24: =SUM('Piamonte HVCDP'!K173+'Requizo HVCDP'!K188+'Lucido HVCDP'!K206+'Rimas HVCDP'!K178) -> 0 | ... W24: =SUM('Piamonte HVCDP'!W173+'Requizo HVCDP'!W188+'Lucido HVCDP'!W206+'Rimas HVCDP'!W178) -> 0
B25: FRUIT TREES
B26: Calamansi | C26: =COUNTA('Piamonte HVCDP'!D175:D184,'Requizo HVCDP'!D190:D199,'Lucido HVCDP'!D208:D217,'Rimas HVCDP'!D180:D189) -> 40 | D26: =SUM('Piamonte HVCDP'!D185+'Requizo HVCDP'!D200+'Lucido HVCDP'!D218+'Rimas HVCDP'!D190) -> 106 | E26: =SUM('Piamonte HVCDP'!E185+'Requizo HVCDP'!E200+'Lucido HVCDP'!E218+'Rimas HVCDP'!E190) -> 23.499 | F26: =SUM('Piamonte HVCDP'!F185+'Requizo HVCDP'!F200+'Lucido HVCDP'!F218+'Rimas HVCDP'!F190) -> 0 | G26: =SUM('Piamonte HVCDP'!G185+'Requizo HVCDP'!G200+'Lucido HVCDP'!G218+'Rimas HVCDP'!G190) -> 23.499 | H26: =SUM('Piamonte HVCDP'!H185+'Requizo HVCDP'!H200+'Lucido HVCDP'!H218+'Rimas HVCDP'!H190) -> 0.4 | I26: =SUM('Piamonte HVCDP'!I185+'Requizo HVCDP'!I200+'Lucido HVCDP'!I218+'Rimas HVCDP'!I190) -> 0 | J26: =SUM('Piamonte HVCDP'!J185+'Requizo HVCDP'!J200+'Lucido HVCDP'!J218+'Rimas HVCDP'!J190) -> 0.4 | K26: =SUM('Piamonte HVCDP'!K185+'Requizo HVCDP'!K200+'Lucido HVCDP'!K218+'Rimas HVCDP'!K190) -> 1.6 | ... W26: =SUM('Piamonte HVCDP'!W185+'Requizo HVCDP'!W200+'Lucido HVCDP'!W218+'Rimas HVCDP'!W190) -> 0
B27: Avocado | C27: =COUNTA('Piamonte HVCDP'!D186:D195,'Requizo HVCDP'!D201:D210,'Lucido HVCDP'!D219:D228,'Rimas HVCDP'!D191:D200) -> 40 | D27: =SUM('Piamonte HVCDP'!D196+'Requizo HVCDP'!D211+'Lucido HVCDP'!D229+'Rimas HVCDP'!D201) -> 97 | E27: =SUM('Piamonte HVCDP'!E196+'Requizo HVCDP'!E211+'Lucido HVCDP'!E229+'Rimas HVCDP'!E201) -> 22.1845 | F27: =SUM('Piamonte HVCDP'!F196+'Requizo HVCDP'!F211+'Lucido HVCDP'!F229+'Rimas HVCDP'!F201) -> 0 | G27: =SUM('Piamonte HVCDP'!G196+'Requizo HVCDP'!G211+'Lucido HVCDP'!G229+'Rimas HVCDP'!G201) -> 22.1845 | H27: =SUM('Piamonte HVCDP'!H196+'Requizo HVCDP'!H211+'Lucido HVCDP'!H229+'Rimas HVCDP'!H201) -> 0.5 | I27: =SUM('Piamonte HVCDP'!I196+'Requizo HVCDP'!I211+'Lucido HVCDP'!I229+'Rimas HVCDP'!I201) -> 0 | J27: =SUM('Piamonte HVCDP'!J196+'Requizo HVCDP'!J211+'Lucido HVCDP'!J229+'Rimas HVCDP'!J201) -> 0.5 | K27: =SUM('Piamonte HVCDP'!K196+'Requizo HVCDP'!K211+'Lucido HVCDP'!K229+'Rimas HVCDP'!K201) -> 2.5 | ... W27: =SUM('Piamonte HVCDP'!W196+'Requizo HVCDP'!W211+'Lucido HVCDP'!W229+'Rimas HVCDP'!W201) -> 0
B28: Papaya | C28: =COUNTA('Piamonte HVCDP'!D197:D206,'Requizo HVCDP'!D212:D221,'Lucido HVCDP'!D230:D239,'Rimas HVCDP'!D202:D211) -> 40 | D28: =SUM('Piamonte HVCDP'!D207+'Requizo HVCDP'!D222+'Lucido HVCDP'!D240+'Rimas HVCDP'!D212) -> 92 | E28: =SUM('Piamonte HVCDP'!E207+'Requizo HVCDP'!E222+'Lucido HVCDP'!E240+'Rimas HVCDP'!E212) -> 17.934 | F28: =SUM('Piamonte HVCDP'!F207+'Requizo HVCDP'!F222+'Lucido HVCDP'!F240+'Rimas HVCDP'!F212) -> 0 | G28: =SUM('Piamonte HVCDP'!G207+'Requizo HVCDP'!G222+'Lucido HVCDP'!G240+'Rimas HVCDP'!G212) -> 17.934 | H28: =SUM('Piamonte HVCDP'!H207+'Requizo HVCDP'!H222+'Lucido HVCDP'!H240+'Rimas HVCDP'!H212) -> 0.6 | I28: =SUM('Piamonte HVCDP'!I207+'Requizo HVCDP'!I222+'Lucido HVCDP'!I240+'Rimas HVCDP'!I212) -> 0 | J28: =SUM('Piamonte HVCDP'!J207+'Requizo HVCDP'!J222+'Lucido HVCDP'!J240+'Rimas HVCDP'!J212) -> 0.6 | K28: =SUM('Piamonte HVCDP'!K207+'Requizo HVCDP'!K222+'Lucido HVCDP'!K240+'Rimas HVCDP'!K212) -> 1.75 | ... W28: =SUM('Piamonte HVCDP'!W207+'Requizo HVCDP'!W222+'Lucido HVCDP'!W240+'Rimas HVCDP'!W212) -> 0
B29: Chico | C29: =COUNTA('Piamonte HVCDP'!D208:D217,'Requizo HVCDP'!D223:D232,'Lucido HVCDP'!D241:D250,'Rimas HVCDP'!D213:D222) -> 40 | D29: =SUM('Piamonte HVCDP'!D218+'Requizo HVCDP'!D233+'Lucido HVCDP'!D251+'Rimas HVCDP'!D223) -> 79 | E29: =SUM('Piamonte HVCDP'!E218+'Requizo HVCDP'!E233+'Lucido HVCDP'!E251+'Rimas HVCDP'!E223) -> 15.622 | F29: =SUM('Piamonte HVCDP'!F218+'Requizo HVCDP'!F233+'Lucido HVCDP'!F251+'Rimas HVCDP'!F223) -> 0 | G29: =SUM('Piamonte HVCDP'!G218+'Requizo HVCDP'!G233+'Lucido HVCDP'!G251+'Rimas HVCDP'!G223) -> 15.622 | H29: =SUM('Piamonte HVCDP'!H218+'Requizo HVCDP'!H233+'Lucido HVCDP'!H251+'Rimas HVCDP'!H223) -> 0.35 | I29: =SUM('Piamonte HVCDP'!I218+'Requizo HVCDP'!I233+'Lucido HVCDP'!I251+'Rimas HVCDP'!I223) -> 0 | J29: =SUM('Piamonte HVCDP'!J218+'Requizo HVCDP'!J233+'Lucido HVCDP'!J251+'Rimas HVCDP'!J223) -> 0.35 | K29: =SUM('Piamonte HVCDP'!K218+'Requizo HVCDP'!K233+'Lucido HVCDP'!K251+'Rimas HVCDP'!K223) -> 0.75 | ... W29: =SUM('Piamonte HVCDP'!W218+'Requizo HVCDP'!W233+'Lucido HVCDP'!W251+'Rimas HVCDP'!W223) -> 0
B30: Rambutan | C30: =COUNTA('Piamonte HVCDP'!D219:D228,'Requizo HVCDP'!D234:D243,'Lucido HVCDP'!D252:D261,'Rimas HVCDP'!D224:D233) -> 40 | D30: =SUM('Piamonte HVCDP'!D229+'Requizo HVCDP'!D244+'Lucido HVCDP'!D262+'Rimas HVCDP'!D234) -> 253 | E30: =SUM('Piamonte HVCDP'!E229+'Requizo HVCDP'!E244+'Lucido HVCDP'!E262+'Rimas HVCDP'!E234) -> 67.1125 | F30: =SUM('Piamonte HVCDP'!F229+'Requizo HVCDP'!F244+'Lucido HVCDP'!F262+'Rimas HVCDP'!F234) -> 0 | G30: =SUM('Piamonte HVCDP'!G229+'Requizo HVCDP'!G244+'Lucido HVCDP'!G262+'Rimas HVCDP'!G234) -> 67.1125 | H30: =SUM('Piamonte HVCDP'!H229+'Requizo HVCDP'!H244+'Lucido HVCDP'!H262+'Rimas HVCDP'!H234) -> 0.09 | I30: =SUM('Piamonte HVCDP'!I229+'Requizo HVCDP'!I244+'Lucido HVCDP'!I262+'Rimas HVCDP'!I234) -> 0 | J30: =SUM('Piamonte HVCDP'!J229+'Requizo HVCDP'!J244+'Lucido HVCDP'!J262+'Rimas HVCDP'!J234) -> 0.09 | K30: =SUM('Piamonte HVCDP'!K229+'Requizo HVCDP'!K244+'Lucido HVCDP'!K262+'Rimas HVCDP'!K234) -> 1.62 | ... W30: =SUM('Piamonte HVCDP'!W229+'Requizo HVCDP'!W244+'Lucido HVCDP'!W262+'Rimas HVCDP'!W234) -> 0
B31: Mango | C31: =COUNTA('Piamonte HVCDP'!D230:D239,'Requizo HVCDP'!D234:D243,'Lucido HVCDP'!D252:D261,'Rimas HVCDP'!D224:D233) -> 40 | D31: =SUM('Piamonte HVCDP'!D240+'Requizo HVCDP'!D255+'Lucido HVCDP'!D273+'Rimas HVCDP'!D245) -> 62 | E31: =SUM('Piamonte HVCDP'!E240+'Requizo HVCDP'!E255+'Lucido HVCDP'!E273+'Rimas HVCDP'!E245) -> 18.606 | F31: =SUM('Piamonte HVCDP'!F240+'Requizo HVCDP'!F255+'Lucido HVCDP'!F273+'Rimas HVCDP'!F245) -> 0 | G31: =SUM('Piamonte HVCDP'!G240+'Requizo HVCDP'!G255+'Lucido HVCDP'!G273+'Rimas HVCDP'!G245) -> 18.606 | H31: =SUM('Piamonte HVCDP'!H240+'Requizo HVCDP'!H255+'Lucido HVCDP'!H273+'Rimas HVCDP'!H245) -> 3.3 | I31: =SUM('Piamonte HVCDP'!I240+'Requizo HVCDP'!I255+'Lucido HVCDP'!I273+'Rimas HVCDP'!I245) -> 0 | J31: =SUM('Piamonte HVCDP'!J240+'Requizo HVCDP'!J255+'Lucido HVCDP'!J273+'Rimas HVCDP'!J245) -> 3.3 | K31: =SUM('Piamonte HVCDP'!K240+'Requizo HVCDP'!K255+'Lucido HVCDP'!K273+'Rimas HVCDP'!K245) -> 39.6 | ... W31: =SUM('Piamonte HVCDP'!W240+'Requizo HVCDP'!W255+'Lucido HVCDP'!W273+'Rimas HVCDP'!W245) -> 0
B32: Lanzones | C32: =COUNTA('Piamonte HVCDP'!D241:D250,'Requizo HVCDP'!D256:D265,'Lucido HVCDP'!D274:D283,'Rimas HVCDP'!D246:D255) -> 40 | D32: =SUM('Piamonte HVCDP'!D251+'Requizo HVCDP'!D266+'Lucido HVCDP'!D284+'Rimas HVCDP'!D256) -> 234 | E32: =SUM('Piamonte HVCDP'!E251+'Requizo HVCDP'!E266+'Lucido HVCDP'!E284+'Rimas HVCDP'!E256) -> 86.7175 | F32: =SUM('Piamonte HVCDP'!F251+'Requizo HVCDP'!F266+'Lucido HVCDP'!F284+'Rimas HVCDP'!F256) -> 0 | G32: =SUM('Piamonte HVCDP'!G251+'Requizo HVCDP'!G266+'Lucido HVCDP'!G284+'Rimas HVCDP'!G256) -> 86.7175 | H32: =SUM('Piamonte HVCDP'!H251+'Requizo HVCDP'!H266+'Lucido HVCDP'!H284+'Rimas HVCDP'!H256) -> 0 | I32: =SUM('Piamonte HVCDP'!I251+'Requizo HVCDP'!I266+'Lucido HVCDP'!I284+'Rimas HVCDP'!I256) -> 0 | J32: =SUM('Piamonte HVCDP'!J251+'Requizo HVCDP'!J266+'Lucido HVCDP'!J284+'Rimas HVCDP'!J256) -> 0 | K32: =SUM('Piamonte HVCDP'!K251+'Requizo HVCDP'!K266+'Lucido HVCDP'!K284+'Rimas HVCDP'!K256) -> 0 | ... W32: =SUM('Piamonte HVCDP'!W251+'Requizo HVCDP'!W266+'Lucido HVCDP'!W284+'Rimas HVCDP'!W256) -> 0
B33: LEAFY VEGETABLES
B34: Malunggay | C34: =COUNTA('Piamonte HVCDP'!D253:D262,'Requizo HVCDP'!D268:D277,'Lucido HVCDP'!D286:D295,'Rimas HVCDP'!D258:D267) -> 21 | D34: =SUM('Piamonte HVCDP'!D263+'Requizo HVCDP'!D278+'Lucido HVCDP'!D296+'Rimas HVCDP'!D268) -> 275 | E34: =SUM('Piamonte HVCDP'!E263+'Requizo HVCDP'!E278+'Lucido HVCDP'!E296+'Rimas HVCDP'!E268) -> 85.5795 | F34: =SUM('Piamonte HVCDP'!F263+'Requizo HVCDP'!F278+'Lucido HVCDP'!F296+'Rimas HVCDP'!F268) -> 0 | G34: =SUM('Piamonte HVCDP'!G263+'Requizo HVCDP'!G278+'Lucido HVCDP'!G296+'Rimas HVCDP'!G268) -> 85.5795 | H34: =SUM('Piamonte HVCDP'!H263+'Requizo HVCDP'!H278+'Lucido HVCDP'!H296+'Rimas HVCDP'!H268) -> 1.5 | I34: =SUM('Piamonte HVCDP'!I263+'Requizo HVCDP'!I278+'Lucido HVCDP'!I296+'Rimas HVCDP'!I268) -> 0 | J34: =SUM('Piamonte HVCDP'!J263+'Requizo HVCDP'!J278+'Lucido HVCDP'!J296+'Rimas HVCDP'!J268) -> 1.5 | K34: =SUM('Piamonte HVCDP'!K263+'Requizo HVCDP'!K278+'Lucido HVCDP'!K296+'Rimas HVCDP'!K268) -> 5 | ... W34: =SUM('Piamonte HVCDP'!W263+'Requizo HVCDP'!W278+'Lucido HVCDP'!W296+'Rimas HVCDP'!W268) -> 0
B35: Mustasa | C35: =COUNTA('Piamonte HVCDP'!D264:D273,'Requizo HVCDP'!D279:D288,'Lucido HVCDP'!D297:D306,'Rimas HVCDP'!D269:D278) -> 5 | D35: =SUM('Piamonte HVCDP'!D274+'Requizo HVCDP'!D289+'Lucido HVCDP'!D307+'Rimas HVCDP'!D279) -> 10 | E35: =SUM('Piamonte HVCDP'!E274+'Requizo HVCDP'!E289+'Lucido HVCDP'!E307+'Rimas HVCDP'!E279) -> 5.25 | F35: =SUM('Piamonte HVCDP'!F274+'Requizo HVCDP'!F289+'Lucido HVCDP'!F307+'Rimas HVCDP'!F279) -> 0 | G35: =SUM('Piamonte HVCDP'!G274+'Requizo HVCDP'!G289+'Lucido HVCDP'!G307+'Rimas HVCDP'!G279) -> 5.25 | H35: =SUM('Piamonte HVCDP'!H274+'Requizo HVCDP'!H289+'Lucido HVCDP'!H307+'Rimas HVCDP'!H279) -> 4.2 | I35: =SUM('Piamonte HVCDP'!I274+'Requizo HVCDP'!I289+'Lucido HVCDP'!I307+'Rimas HVCDP'!I279) -> 0 | J35: =SUM('Piamonte HVCDP'!J274+'Requizo HVCDP'!J289+'Lucido HVCDP'!J307+'Rimas HVCDP'!J279) -> 4.2 | K35: =SUM('Piamonte HVCDP'!K274+'Requizo HVCDP'!K289+'Lucido HVCDP'!K307+'Rimas HVCDP'!K279) -> 27 | ... W35: =SUM('Piamonte HVCDP'!W274+'Requizo HVCDP'!W289+'Lucido HVCDP'!W307+'Rimas HVCDP'!W279) -> 0
B36: Pechay | C36: =COUNTA('Piamonte HVCDP'!D275:D284,'Requizo HVCDP'!D290:D299,'Lucido HVCDP'!D308:D317,'Rimas HVCDP'!D280:D289) -> 17 | D36: =SUM('Piamonte HVCDP'!D285+'Requizo HVCDP'!D300+'Lucido HVCDP'!D318+'Rimas HVCDP'!D290) -> 114 | E36: =SUM('Piamonte HVCDP'!E285+'Requizo HVCDP'!E300+'Lucido HVCDP'!E318+'Rimas HVCDP'!E290) -> 85.69 | F36: =SUM('Piamonte HVCDP'!F285+'Requizo HVCDP'!F300+'Lucido HVCDP'!F318+'Rimas HVCDP'!F290) -> 0 | G36: =SUM('Piamonte HVCDP'!G285+'Requizo HVCDP'!G300+'Lucido HVCDP'!G318+'Rimas HVCDP'!G290) -> 85.69 | H36: =SUM('Piamonte HVCDP'!H285+'Requizo HVCDP'!H300+'Lucido HVCDP'!H318+'Rimas HVCDP'!H290) -> 65.75 | I36: =SUM('Piamonte HVCDP'!I285+'Requizo HVCDP'!I300+'Lucido HVCDP'!I318+'Rimas HVCDP'!I290) -> 0 | J36: =SUM('Piamonte HVCDP'!J285+'Requizo HVCDP'!J300+'Lucido HVCDP'!J318+'Rimas HVCDP'!J290) -> 65.75 | K36: =SUM('Piamonte HVCDP'!K285+'Requizo HVCDP'!K300+'Lucido HVCDP'!K318+'Rimas HVCDP'!K290) -> 530.38 | ... W36: =SUM('Piamonte HVCDP'!W285+'Requizo HVCDP'!W300+'Lucido HVCDP'!W318+'Rimas HVCDP'!W290) -> 0
B37: ROOTCROPS
B38: Radish | C38: =COUNTA('Lucido HVCDP'!D320:D329) -> 0 | D38: =SUM('Lucido HVCDP'!D330) -> 0 | E38: =SUM('Lucido HVCDP'!E330) -> 0 | F38: =SUM('Lucido HVCDP'!F330) -> 0 | G38: =SUM('Lucido HVCDP'!G330) -> 0 | H38: =SUM('Lucido HVCDP'!H330) -> 0 | I38: =SUM('Lucido HVCDP'!I330) -> 0 | J38: =SUM('Lucido HVCDP'!J330) -> 0 | K38: =SUM('Lucido HVCDP'!K330) -> 0 | ... W38: =SUM('Lucido HVCDP'!W330) -> 0
B39: Ginger | C39: =COUNTA('Piamonte HVCDP'!D287:D296,'Requizo HVCDP'!D302:D311,'Lucido HVCDP'!D331:D340,'Rimas HVCDP'!D292:D301) -> 3 | D39: =SUM('Piamonte HVCDP'!D297+'Requizo HVCDP'!D312+'Lucido HVCDP'!D341+'Rimas HVCDP'!D302) -> 2 | E39: =SUM('Piamonte HVCDP'!E297+'Requizo HVCDP'!E312+'Lucido HVCDP'!E341+'Rimas HVCDP'!E302) -> 0.5 | F39: =SUM('Piamonte HVCDP'!F297+'Requizo HVCDP'!F312+'Lucido HVCDP'!F341+'Rimas HVCDP'!F302) -> 0 | G39: =SUM('Piamonte HVCDP'!G297+'Requizo HVCDP'!G312+'Lucido HVCDP'!G341+'Rimas HVCDP'!G302) -> 0.5 | H39: =SUM('Piamonte HVCDP'!H297+'Requizo HVCDP'!H312+'Lucido HVCDP'!H341+'Rimas HVCDP'!H302) -> 0.25 | I39: =SUM('Piamonte HVCDP'!I297+'Requizo HVCDP'!I312+'Lucido HVCDP'!I341+'Rimas HVCDP'!I302) -> 0 | J39: =SUM('Piamonte HVCDP'!J297+'Requizo HVCDP'!J312+'Lucido HVCDP'!J341+'Rimas HVCDP'!J302) -> 0.25 | K39: =SUM('Piamonte HVCDP'!K297+'Requizo HVCDP'!K312+'Lucido HVCDP'!K341+'Rimas HVCDP'!K302) -> 0.12 | ... W39: =SUM('Piamonte HVCDP'!W297+'Requizo HVCDP'!W312+'Lucido HVCDP'!W341+'Rimas HVCDP'!W302) -> 0
B40: Ubi | C40: =COUNTA('Piamonte HVCDP'!D298:D307,'Requizo HVCDP'!D313:D322,'Lucido HVCDP'!D342:D351,'Rimas HVCDP'!D303:D312) -> 2 | D40: =SUM('Piamonte HVCDP'!D308+'Requizo HVCDP'!D323+'Lucido HVCDP'!D352+'Rimas HVCDP'!D313) -> 1 | E40: =SUM('Piamonte HVCDP'!E308+'Requizo HVCDP'!E323+'Lucido HVCDP'!E352+'Rimas HVCDP'!E313) -> 0.05 | F40: =SUM('Piamonte HVCDP'!F308+'Requizo HVCDP'!F323+'Lucido HVCDP'!F352+'Rimas HVCDP'!F313) -> 0 | G40: =SUM('Piamonte HVCDP'!G308+'Requizo HVCDP'!G323+'Lucido HVCDP'!G352+'Rimas HVCDP'!G313) -> 0.05 | H40: =SUM('Piamonte HVCDP'!H308+'Requizo HVCDP'!H323+'Lucido HVCDP'!H352+'Rimas HVCDP'!H313) -> 0 | I40: =SUM('Piamonte HVCDP'!I308+'Requizo HVCDP'!I323+'Lucido HVCDP'!I352+'Rimas HVCDP'!I313) -> 0 | J40: =SUM('Piamonte HVCDP'!J308+'Requizo HVCDP'!J323+'Lucido HVCDP'!J352+'Rimas HVCDP'!J313) -> 0 | K40: =SUM('Piamonte HVCDP'!K308+'Requizo HVCDP'!K323+'Lucido HVCDP'!K352+'Rimas HVCDP'!K313) -> 0 | ... W40: =SUM('Piamonte HVCDP'!W308+'Requizo HVCDP'!W323+'Lucido HVCDP'!W352+'Rimas HVCDP'!W313) -> 0
B41: Peanut | C41: =COUNTA('Piamonte HVCDP'!D309:D318,'Requizo HVCDP'!D324:D333,'Lucido HVCDP'!D353:D362,'Rimas HVCDP'!D314:D323) -> 4 | D41: =SUM('Piamonte HVCDP'!D319+'Requizo HVCDP'!D334+'Lucido HVCDP'!D363+'Rimas HVCDP'!D324) -> 3 | E41: =SUM('Piamonte HVCDP'!E319+'Requizo HVCDP'!E334+'Lucido HVCDP'!E363+'Rimas HVCDP'!E324) -> 0.8 | F41: =SUM('Piamonte HVCDP'!F319+'Requizo HVCDP'!F334+'Lucido HVCDP'!F363+'Rimas HVCDP'!F324) -> 0 | G41: =SUM('Piamonte HVCDP'!G319+'Requizo HVCDP'!G334+'Lucido HVCDP'!G363+'Rimas HVCDP'!G324) -> 0.8 | H41: =SUM('Piamonte HVCDP'!H319+'Requizo HVCDP'!H334+'Lucido HVCDP'!H363+'Rimas HVCDP'!H324) -> 0 | I41: =SUM('Piamonte HVCDP'!I319+'Requizo HVCDP'!I334+'Lucido HVCDP'!I363+'Rimas HVCDP'!I324) -> 0 | J41: =SUM('Piamonte HVCDP'!J319+'Requizo HVCDP'!J334+'Lucido HVCDP'!J363+'Rimas HVCDP'!J324) -> 0 | K41: =SUM('Piamonte HVCDP'!K319+'Requizo HVCDP'!K334+'Lucido HVCDP'!K363+'Rimas HVCDP'!K324) -> 0 | ... W41: =SUM('Piamonte HVCDP'!W319+'Requizo HVCDP'!W334+'Lucido HVCDP'!W363+'Rimas HVCDP'!W324) -> 0
...

Sheet Piamonte Summary
A1: MONTHLY AGRICULTURAL/FISHERY SITUATION REPORT
A2: Barangays Covered: Altura Matanda, Altura South, Banadero, Bilog-Bilog, Luyos, Malaking Pulo, Montana, Sala, Santor, Sulpoc
A4: District | B4: Commodity | C4: No. of Barangays Covered | D4: This Mo. | E4: Stage of Growth | F4: No. of Barangays Covered | G4: Area Harvested | H4: Estimated Production
A5: III | B5: FRUIT VEGETABLES
B6: Eggplant | C6: =COUNTA('[1]Piamonte HVCDP'!F6:F15) -> 0 | D6: ='[1]Piamonte HVCDP'!F16 -> 0 | E6: =IF(D6>0, "Vegetative", "No Planting") -> No Planting | F6: =COUNTA('[1]Piamonte HVCDP'!L5:L15) -> 1 | G6: ='[1]Piamonte HVCDP'!I16 -> 0.6 | H6: =IF(G6=0,"No Production",'[1]Piamonte HVCDP'!L16) -> 6.6
B7: Sitao | C7: =COUNTA('[1]Piamonte HVCDP'!F17:F26) -> 0 | D7: ='[1]Piamonte HVCDP'!F27 -> 0 | E7: =IF(D7>0, "Vegetative", "No Planting") -> No Planting | F7: =COUNTA('[1]Piamonte HVCDP'!L17:L26) -> 0 | G7: ='[1]Piamonte HVCDP'!I27 -> 0 | H7: =IF(G7=0,"No Production",'[1]Piamonte HVCDP'!L27) -> No Production
B8: Squash | C8: =COUNTA('[1]Piamonte HVCDP'!F28:F37) -> 0 | D8: ='[1]Piamonte HVCDP'!F38 -> 0 | E8: =IF(D8>0, "Vegetative", "No Planting") -> No Planting | F8: =COUNTA('[1]Piamonte HVCDP'!I28:I37) -> 0 | G8: ='[1]Piamonte HVCDP'!I38 -> 0 | H8: =IF(G8=0,"No Production",'[1]Piamonte HVCDP'!L38) -> No Production
B9: Okra | C9: =COUNTA('[1]Piamonte HVCDP'!F39:F48) -> 1 | D9: ='[1]Piamonte HVCDP'!F49 -> 0.25 | E9: =IF(D9>0, "Vegetative", "No Planting") -> Vegetative | F9: =COUNTA('[1]Piamonte HVCDP'!I39:I48) -> 0 | G9: ='[1]Piamonte HVCDP'!H49 -> 3.25 | H9: =IF(G9=0,"No Production",'[1]Piamonte HVCDP'!L49) -> 0
B10: Patola | C10: =COUNTA('[1]Piamonte HVCDP'!F50:F59) -> 0 | D10: ='[1]Piamonte HVCDP'!F60 -> 0 | E10: =IF(D10>0, "Vegetative", "No Planting") -> No Planting | F10: =COUNTA('[1]Piamonte HVCDP'!I61:I70) -> 0 | G10: ='[1]Piamonte HVCDP'!H60 -> 3.85 | H10: =IF(G10=0,"No Production",'[1]Piamonte HVCDP'!L60) -> 0
B11: Sigarilyas | C11: =COUNTA('[1]Piamonte HVCDP'!F61:F70) -> 0 | D11: ='[1]Piamonte HVCDP'!F71 -> 0 | E11: =IF(D11>0, "Vegetative", "No Planting") -> No Planting | F11: =COUNTA('[1]Piamonte HVCDP'!I61:I70) -> 0 | G11: ='[1]Piamonte HVCDP'!H71 -> 16.3 | H11: =IF(G11=0,"No Production",'[1]Piamonte HVCDP'!L71) -> 0
B12: Upo | C12: =COUNTA('[1]Piamonte HVCDP'!F72:F81) -> 0 | D12: ='[1]Piamonte HVCDP'!F82 -> 0 | E12: =IF(D12>0, "Vegetative", "No Planting") -> No Planting | F12: =COUNTA('[1]Piamonte HVCDP'!I72:I81) -> 0 | G12: ='[1]Piamonte HVCDP'!I82 -> 0 | H12: =IF(G12=0,"No Production",'[1]Piamonte HVCDP'!L82) -> No Production
B13: Ampalaya | C13: =COUNTA('[1]Piamonte HVCDP'!F83:F92) -> 0 | D13: ='[1]Piamonte HVCDP'!F93 -> 0 | E13: =IF(D13>0, "Vegetative", "No Planting") -> No Planting | F13: =COUNTA('[1]Piamonte HVCDP'!I83:I92) -> 0 | G13: ='[1]Piamonte HVCDP'!I93 -> 0 | H13: =IF(G13=0,"No Production",'[1]Piamonte HVCDP'!L93) -> No Production
B14: Pipino | C14: =COUNTA('[1]Piamonte HVCDP'!F94:F103) -> 0 | D14: ='[1]Piamonte HVCDP'!F104 -> 0 | E14: =IF(D14>0, "Vegetative", "No Planting") -> No Planting | F14: =COUNTA('[1]Piamonte HVCDP'!I94:I103) -> 0 | G14: ='[1]Piamonte HVCDP'!I104 -> 0 | H14: =IF(G14=0,"No Production",'[1]Piamonte HVCDP'!L104) -> No Production
B15: Sili | C15: =COUNTA('[1]Piamonte HVCDP'!F105:F114) -> 0 | D15: ='[1]Piamonte HVCDP'!F115 -> 0 | E15: =IF(D15>0, "Vegetative", "No Planting") -> No Planting | F15: =COUNTA('[1]Piamonte HVCDP'!I105:I114) -> 0 | G15: ='[1]Piamonte HVCDP'!I115 -> 0 | H15: =IF(G15=0,"No Production",'[1]Piamonte HVCDP'!L115) -> No Production
B16: Beans | C16: =COUNTA('[1]Piamonte HVCDP'!F116:F125) -> 0 | D16: ='[1]Piamonte HVCDP'!F126 -> 0 | E16: =IF(D16>0, "Vegetative", "No Planting") -> No Planting | F16: =COUNTA('[1]Piamonte HVCDP'!I116:I125) -> 0 | G16: ='[1]Piamonte HVCDP'!I126 -> 0 | H16: =IF(G16=0,"No Production",'[1]Piamonte HVCDP'!L126) -> No Production
B17: Paayap | C17: =COUNTA('[1]Piamonte HVCDP'!F127:F136) -> 0 | D17: ='[1]Piamonte HVCDP'!F137 -> 0 | E17: =IF(D17>0, "Vegetative", "No Planting") -> No Planting | F17: =COUNTA('[1]Piamonte HVCDP'!I127:I136) -> 0 | G17: ='[1]Piamonte HVCDP'!I137 -> 0 | H17: =IF(G17=0,"No Production",'[1]Piamonte HVCDP'!L137) -> No Production
B18: Tomato | C18: =COUNTA('[1]Piamonte HVCDP'!F138:F147) -> 0 | D18: ='[1]Piamonte HVCDP'!F148 -> 0 | E18: =IF(D18>0, "Vegetative", "No Planting") -> No Planting | F18: =COUNTA('[1]Piamonte HVCDP'!I138:I147) -> 0 | G18: ='[1]Piamonte HVCDP'!I148 -> 0 | H18: =IF(G18=0,"No Production",'[1]Piamonte HVCDP'!L148) -> No Production
B19: INDUSTRIAL CROPS
B20: Banana | C20: =COUNTA('[1]Piamonte HVCDP'!F150:F159) -> 0 | D20: ='[1]Piamonte HVCDP'!F160 -> 0 | E20: =IF(D20>0, "Vegetative", "No Planting") -> No Planting | F20: =COUNTA('[1]Piamonte HVCDP'!I149:I159) -> 0 | G20: ='[1]Piamonte HVCDP'!I160 -> 0 | H20: =IF(G20=0,"No Production",'[1]Piamonte HVCDP'!L160) -> No Production
B21: Cacao | C21: =COUNTA('[1]Piamonte HVCDP'!F161:F170) -> 0 | D21: ='[1]Piamonte HVCDP'!F171 -> 0 | E21: =IF(D21>0, "Vegetative", "No Planting") -> No Planting | F21: =COUNTA('[1]Piamonte HVCDP'!I161:I170) -> 0 | G21: ='[1]Piamonte HVCDP'!I171 -> 0 | H21: =IF(G21=0,"No Production",'[1]Piamonte HVCDP'!L171) -> No Production
B22: Coffee | C22: =COUNTA('[1]Piamonte HVCDP'!F172) -> 0 | D22: ='[1]Piamonte HVCDP'!F173 -> 0 | E22: =IF(D22>0, "Vegetative", "No Planting") -> No Planting | F22: =COUNTA('[1]Piamonte HVCDP'!I172) -> 0 | G22: ='[1]Piamonte HVCDP'!I173 -> 0 | H22: =IF(G22=0,"No Production",'[1]Piamonte HVCDP'!L173) -> No Production
B23: FRUIT TREES
B24: Calamansi | C24: =COUNTA('[1]Piamonte HVCDP'!F175:F184) -> 0 | D24: ='[1]Piamonte HVCDP'!F185 -> 0 | E24: =IF(D24>0, "Vegetative", "No Planting") -> No Planting | F24: =COUNTA('[1]Piamonte HVCDP'!I175:I184) -> 0 | G24: ='[1]Piamonte HVCDP'!I185 -> 0 | H24: =IF(G24=0,"No Production",'[1]Piamonte HVCDP'!L185) -> No Production
B25: Avocado | C25: =COUNTA('[1]Piamonte HVCDP'!F186:F195) -> 0 | D25: ='[1]Piamonte HVCDP'!F196 -> 0 | E25: =IF(D25>0, "Vegetative", "No Planting") -> No Planting | F25: =COUNTA('[1]Piamonte HVCDP'!I186:I195) -> 0 | G25: ='[1]Piamonte HVCDP'!I196 -> 0 | H25: =IF(G25=0,"No Production",'[1]Piamonte HVCDP'!L196) -> No Production
B26: Papaya | C26: =COUNTA('[1]Piamonte HVCDP'!F197:F206) -> 0 | D26: ='[1]Piamonte HVCDP'!F207 -> 0 | E26: =IF(D26>0, "Vegetative", "No Planting") -> No Planting | F26: =COUNTA('[1]Piamonte HVCDP'!I197:I206) -> 0 | G26: ='[1]Piamonte HVCDP'!I207 -> 0 | H26: =IF(G26=0,"No Production",'[1]Piamonte HVCDP'!L207) -> No Production
B27: Chico | C27: =COUNTA('[1]Piamonte HVCDP'!F208:F217) -> 0 | D27: ='[1]Piamonte HVCDP'!F218 -> 0 | E27: =IF(D27>0, "Vegetative", "No Planting") -> No Planting | F27: =COUNTA('[1]Piamonte HVCDP'!H208:H217) -> 0 | G27: ='[1]Piamonte HVCDP'!I218 -> 0 | H27: =IF(G27=0,"No Production",'[1]Piamonte HVCDP'!L218) -> No Production
B28: Rambutan | C28: =COUNTA('[1]Piamonte HVCDP'!F219:F228) -> 0 | D28: ='[1]Piamonte HVCDP'!F229 -> 0 | E28: =IF(D28>0, "Vegetative", "No Planting") -> No Planting | F28: =COUNTA('[1]Piamonte HVCDP'!I219:I228) -> 0 | G28: ='[1]Piamonte HVCDP'!I229 -> 0 | H28: =IF(G28=0,"No Production",'[1]Piamonte HVCDP'!L229) -> No Production
B29: Mango | C29: =COUNTA('[1]Piamonte HVCDP'!F230:F239) -> 0 | D29: ='[1]Piamonte HVCDP'!F240 -> 0 | E29: =IF(D29>0, "Vegetative", "No Planting") -> No Planting | F29: =COUNTA('[1]Piamonte HVCDP'!I230:I239) -> 0 | G29: ='[1]Piamonte HVCDP'!I240 -> 0 | H29: =IF(G29=0,"No Production",'[1]Piamonte HVCDP'!L240) -> No Production
B30: Lanzones | C30: =COUNTA('[1]Piamonte HVCDP'!F241:F250) -> 0 | D30: ='[1]Piamonte HVCDP'!F251 -> 0 | E30: =IF(D30>0, "Vegetative", "No Planting") -> No Planting | F30: =COUNTA('[1]Piamonte HVCDP'!I241:I250) -> 0 | G30: ='[1]Piamonte HVCDP'!I251 -> 0 | H30: =IF(G30=0,"No Production",'[1]Piamonte HVCDP'!L251) -> No Production
B31: LEAFY VEGETABLES
B32: Malunggay | C32: =COUNTA('[1]Piamonte HVCDP'!F253:F262) -> 0 | D32: ='[1]Piamonte HVCDP'!F263 -> 0 | E32: =IF(D32>0, "Vegetative", "No Planting") -> No Planting | F32: =COUNTA('[1]Piamonte HVCDP'!J253:J262) -> 0 | G32: ='[1]Piamonte HVCDP'!I263 -> 0 | H32: =IF(G32=0,"No Production",'[1]Piamonte HVCDP'!L263) -> No Production
B33: Mustasa | C33: =COUNTA('[1]Piamonte HVCDP'!F264:F273) -> 0 | D33: ='[1]Piamonte HVCDP'!F274 -> 0 | E33: =IF(D33>0, "Vegetative", "No Planting") -> No Planting | F33: =COUNTA('[1]Piamonte HVCDP'!I264:I273) -> 0 | G33: ='[1]Piamonte HVCDP'!I274 -> 0 | H33: =IF(G33=0,"No Production",'[1]Piamonte HVCDP'!L274) -> No Production
B34: Pechay | C34: =COUNTA('[1]Piamonte HVCDP'!F275:F284) -> 1 | D34: ='[1]Piamonte HVCDP'!F285 -> 0.3 | E34: =IF(D34>0, "Vegetative", "No Planting") -> Vegetative | F34: =COUNTA('[1]Piamonte HVCDP'!I275:I284) -> 1 | G34: ='[1]Piamonte HVCDP'!I285 -> 3 | H34: =IF(G34=0,"No Production",'[1]Piamonte HVCDP'!L285) -> 0.9
B35: ROOTCROPS
B36: Ginger | C36: =COUNTA('[1]Piamonte HVCDP'!F287:F296) -> 0 | D36: ='[1]Piamonte HVCDP'!F297 -> 0 | E36: =IF(D36>0, "Vegetative", "No Planting") -> No Planting | F36: =COUNTA('[1]Piamonte HVCDP'!I287:I296) -> 0 | G36: ='[1]Piamonte HVCDP'!I297 -> 0 | H36: =IF(G36=0,"No Production",'[1]Piamonte HVCDP'!L297) -> No Production
B37: Ubi | C37: =COUNTA('[1]Piamonte HVCDP'!F298:F307) -> 0 | D37: ='[1]Piamonte HVCDP'!F308 -> 0 | E37: =IF(D37>0, "Vegetative", "No Planting") -> No Planting | F37: =COUNTA('[1]Piamonte HVCDP'!I298:I307) -> 0 | G37: ='[1]Piamonte HVCDP'!I308 -> 0 | H37: =IF(G37=0,"No Production",'[1]Piamonte HVCDP'!L308) -> No Production
B38: Peanut | C38: =COUNTA('[1]Piamonte HVCDP'!F309:F318) -> 0 | D38: ='[1]Piamonte HVCDP'!F319 -> 0 | E38: =IF(D38>0, "Vegetative", "No Planting") -> No Planting | F38: =COUNTA('[1]Piamonte HVCDP'!I309:I318) -> 0 | G38: ='[1]Piamonte HVCDP'!I319 -> 0 | H38: =IF(G38=0,"No Production",'[1]Piamonte HVCDP'!L319) -> No Production
B39: Sweet Potato | C39: =COUNTA('[1]Piamonte HVCDP'!F320:F329) -> 0 | D39: ='[1]Piamonte HVCDP'!F330 -> 0 | E39: =IF(D39>0, "Vegetative", "No Planting") -> No Planting | F39: =COUNTA('[1]Piamonte HVCDP'!I320:I329) -> 0 | G39: ='[1]Piamonte HVCDP'!I330 -> 0 | H39: =IF(G39=0,"No Production",'[1]Piamonte HVCDP'!L330) -> No Production
B40: BULB
B41: Garlic | C41: =COUNTA('[1]Piamonte HVCDP'!F332:F341) -> 0 | D41: ='[1]Piamonte HVCDP'!F342 -> 0 | E41: =IF(D41>0, "Vegetative", "No Planting") -> No Planting | F41: =COUNTA('[1]Piamonte HVCDP'!I332:I341) -> 0 | G41: ='[1]Piamonte HVCDP'!I342 -> 0 | H41: =IF(G41=0,"No Production",'[1]Piamonte HVCDP'!L342) -> No Production
...

Sheet Lucido Summary
A1: MONTHLY AGRICULTURAL/FISHERY SITUATION REPORT
A2: Barangays Covered: Banjo East, Banjo West, Boot, Cale, Darasa, Hidalgo, Maugat, Natatas, Pantay Bata, Suplang
A4: District | B4: Commodity | C4: No. of Barangays Covered | D4: This Mo. | E4: Stage of Growth | F4: No. of Barangays Covered | G4: Area Harvested | H4: Estimated Production
A5: III | B5: FRUIT VEGETABLES
B6: Eggplant | C6: =COUNTA('[2]Lucido HVCDP'!F6:F15) -> 0 | D6: ='[2]Lucido HVCDP'!F16 -> 0 | E6: =IF(D6>0, "Vegetative", "No Planting") -> No Planting | F6: =COUNTA('[2]Lucido HVCDP'!I6:I15) -> 1 | G6: ='[2]Lucido HVCDP'!I16 -> 0.25 | H6: =IF(G6=0,"No Production",'[2]Lucido HVCDP'!L16) -> 1.25
B7: Sitao | C7: =COUNTA('[2]Lucido HVCDP'!F17:F26) -> 2 | D7: ='[2]Lucido HVCDP'!F27 -> 1.05 | E7: =IF(D7>0, "Vegetative", "No Planting") -> Vegetative | F7: =COUNTA('[2]Lucido HVCDP'!I17:I26) -> 0 | G7: ='[2]Lucido HVCDP'!I27 -> 0 | H7: =IF(G7=0,"No Production",'[2]Lucido HVCDP'!L27) -> No Production
B8: Squash | C8: =COUNTA('[2]Lucido HVCDP'!F28:F37) -> 0 | D8: ='[2]Lucido HVCDP'!F38 -> 0 | E8: =IF(D8>0, "Vegetative", "No Planting") -> No Planting | F8: =COUNTA('[2]Lucido HVCDP'!I28:I37) -> 0 | G8: ='[2]Lucido HVCDP'!I38 -> 0 | H8: =IF(G8=0,"No Production",'[2]Lucido HVCDP'!L38) -> No Production
B9: Okra | C9: =COUNTA('[2]Lucido HVCDP'!F39:F48) -> 0 | D9: ='[2]Lucido HVCDP'!F49 -> 0 | E9: =IF(D9>0, "Vegetative", "No Planting") -> No Planting | F9: =COUNTA('[2]Lucido HVCDP'!I39:I48) -> 0 | G9: ='[2]Lucido HVCDP'!I49 -> 0 | H9: =IF(G9=0,"No Production",'[2]Lucido HVCDP'!L49) -> No Production
B10: Patola | C10: =COUNTA('[2]Lucido HVCDP'!G50:G59) -> 1 | D10: ='[2]Lucido HVCDP'!F60 -> 0 | E10: =IF(D10>0, "Vegetative", "No Planting") -> No Planting | F10: =COUNTA('[2]Lucido HVCDP'!I50:I59) -> 0 | G10: ='[2]Lucido HVCDP'!I60 -> 0 | H10: =IF(G10=0,"No Production",'[2]Lucido HVCDP'!L60) -> No Production
B11: Sigarilyas | C11: =COUNTA('[2]Lucido HVCDP'!F61:F70) -> 0 | D11: ='[2]Lucido HVCDP'!F71 -> 0 | E11: =IF(D11>0, "Vegetative", "No Planting") -> No Planting | F11: =COUNTA('[2]Lucido HVCDP'!I61:I70) -> 0 | G11: ='[2]Lucido HVCDP'!I71 -> 0 | H11: =IF(G11=0,"No Production",'[2]Lucido HVCDP'!L71) -> No Production
B12: Upo | C12: =COUNTA('[2]Lucido HVCDP'!F72:F81) -> 1 | D12: ='[2]Lucido HVCDP'!F82 -> 0.5 | E12: =IF(D12>0, "Vegetative", "No Planting") -> Vegetative | F12: =COUNTA('[2]Lucido HVCDP'!I72:I81) -> 2 | G12: ='[2]Lucido HVCDP'!I82 -> 0.44 | H12: =IF(G12=0,"No Production",'[2]Lucido HVCDP'!L82) -> 2.2
B13: Ampalaya | C13: =COUNTA('[2]Lucido HVCDP'!F83:F92) -> 2 | D13: ='[2]Lucido HVCDP'!F93 -> 2.2 | E13: =IF(D13>0, "Vegetative", "No Planting") -> Vegetative | F13: =COUNTA('[2]Lucido HVCDP'!I83:I92) -> 0 | G13: ='[2]Lucido HVCDP'!I93 -> 0 | H13: =IF(G13=0,"No Production",'[2]Lucido HVCDP'!L93) -> No Production
B14: Pipino | C14: =COUNTA('[2]Lucido HVCDP'!F94:F103) -> 0 | D14: ='[2]Lucido HVCDP'!F104 -> 0 | E14: =IF(D14>0, "Vegetative", "No Planting") -> No Planting | F14: =COUNTA('[2]Lucido HVCDP'!I94:I103) -> 0 | G14: ='[2]Lucido HVCDP'!I104 -> 0 | H14: =IF(G14=0,"No Production",'[2]Lucido HVCDP'!L104) -> No Production
